Workbook

Sheet Dashboard
B1: Household Expense Dashboard
B2: ="Period: "&TEXT(MAX($Q$3,$Q$7),"d mmm yyyy")&" to "&TEXT(MIN($Q$4,$Q$8),"d mmm yyyy")&" | "&IF($G$4="Yes","including","excluding")&" one-off costs" | P2: Calculation helpers (hidden) - do not edit
P3: Start date | Q3: =IF($C$4="All time",DATE(2000,1,1),IF(ISNUMBER($C$4),DATE(YEAR($C$4),MONTH($C$4),1),DATEVALUE("1 "&$C$4))) | R3: n | S3: category | T3: sort key | U3: spent
B4: Month | C4: All time | E4: Include one-off costs? | G4: Yes | I4: Pick a month (or All time) and Yes/No for one-offs - every number below updates. | P4: End date | Q4: =IF($C$4="All time",DATE(2100,12,31),EDATE(Q3,1)-1) | R4: 1 | S4: =IF(INDEX(Lists!$H$4:$AA$4,1,R4)="","",INDEX(Lists!$H$4:$AA$4,1,R4)) | T4: =IF(S4="",-1,U4)-R4/1000000000 | U4: =IF(S4="",0,SUMIFS('Expense Log'!$I$5:$I$3000,'Expense Log'!$A$5:$A$3000,">="&$Q$3,'Expense Log'!$A$5:$A$3000,"<="&$Q$4,'Expense Log'!$C$5:$C$3000,S4,'Expense Log'!$J$5:$J$3000,$Q$5))
P5: One-off criterion | Q5: =IF($G$4="Yes","<>zzzz","<>Yes") | R5: 2 | S5: =IF(INDEX(Lists!$H$4:$AA$4,1,R5)="","",INDEX(Lists!$H$4:$AA$4,1,R5)) | T5: =IF(S5="",-1,U5)-R5/1000000000 | U5: =IF(S5="",0,SUMIFS('Expense Log'!$I$5:$I$3000,'Expense Log'!$A$5:$A$3000,">="&$Q$3,'Expense Log'!$A$5:$A$3000,"<="&$Q$4,'Expense Log'!$C$5:$C$3000,S5,'Expense Log'!$J$5:$J$3000,$Q$5))
B6: TOTAL SPENT | D6: FIXED NEEDS | F6: VARIABLE WANTS | H6: DAILY AVERAGE | J6: VS PREVIOUS MONTH | L6: TOP CATEGORY | P6: Months in period | Q6: =IF($C$4="All time",MAX(1,COUNT('Monthly Summary'!$B$3:$Y$3)),1) | R6: 3 | S6: =IF(INDEX(Lists!$H$4:$AA$4,1,R6)="","",INDEX(Lists!$H$4:$AA$4,1,R6)) | T6: =IF(S6="",-1,U6)-R6/1000000000 | U6: =IF(S6="",0,SUMIFS('Expense Log'!$I$5:$I$3000,'Expense Log'!$A$5:$A$3000,">="&$Q$3,'Expense Log'!$A$5:$A$3000,"<="&$Q$4,'Expense Log'!$C$5:$C$3000,S6,'Expense Log'!$J$5:$J$3000,$Q$5))
B7: =$Q$12 | D7: =SUMIFS('Expense Log'!$I$5:$I$3000,'Expense Log'!$A$5:$A$3000,">="&$Q$3,'Expense Log'!$A$5:$A$3000,"<="&$Q$4,'Expense Log'!$E$5:$E$3000,Lists!$C$5,'Expense Log'!$J$5:$J$3000,$Q$5) | F7: =SUMIFS('Expense Log'!$I$5:$I$3000,'Expense Log'!$A$5:$A$3000,">="&$Q$3,'Expense Log'!$A$5:$A$3000,"<="&$Q$4,'Expense Log'!$E$5:$E$3000,Lists!$C$6,'Expense Log'!$J$5:$J$3000,$Q$5) | H7: =$Q$12/$Q$9 | J7: =IF($Q$13="","-",IF($Q$13=0,"n/a",$Q$12/$Q$13-1)) | L7: =IF($Q$12=0,"-",B12) | P7: First date in log | Q7: =IF(COUNT('Expense Log'!$A$5:$A$3000)=0,0,MIN('Expense Log'!$A$5:$A$3000)) | R7: 4 | S7: =IF(INDEX(Lists!$H$4:$AA$4,1,R7)="","",INDEX(Lists!$H$4:$AA$4,1,R7)) | T7: =IF(S7="",-1,U7)-R7/1000000000 | U7: =IF(S7="",0,SUMIFS('Expense Log'!$I$5:$I$3000,'Expense Log'!$A$5:$A$3000,">="&$Q$3,'Expense Log'!$A$5:$A$3000,"<="&$Q$4,'Expense Log'!$C$5:$C$3000,S7,'Expense Log'!$J$5:$J$3000,$Q$5))
B8: =$Q$14&" transactions" | D8: =IF($Q$12=0,"",TEXT(D7/$Q$12,"0%")&" of spend") | F8: =IF($Q$12=0,"",TEXT(F7/$Q$12,"0%")&" of spend") | H8: ="over "&$Q$9&" days" | J8: =IF($Q$13="","All-time view","Prev. month: "&TEXT($Q$13,"$#,##0")) | L8: =IF($Q$12=0,"",TEXT(D12,"$#,##0")&" ("&TEXT(E12,"0%")&")") | P8: Last date in log | Q8: =IF(COUNT('Expense Log'!$A$5:$A$3000)=0,0,MAX('Expense Log'!$A$5:$A$3000)) | R8: 5 | S8: =IF(INDEX(Lists!$H$4:$AA$4,1,R8)="","",INDEX(Lists!$H$4:$AA$4,1,R8)) | T8: =IF(S8="",-1,U8)-R8/1000000000 | U8: =IF(S8="",0,SUMIFS('Expense Log'!$I$5:$I$3000,'Expense Log'!$A$5:$A$3000,">="&$Q$3,'Expense Log'!$A$5:$A$3000,"<="&$Q$4,'Expense Log'!$C$5:$C$3000,S8,'Expense Log'!$J$5:$J$3000,$Q$5))
P9: Days in period (with data) | Q9: =MAX(1,MIN(Q4,Q8)-MAX(Q3,Q7)+1) | R9: 6 | S9: =IF(INDEX(Lists!$H$4:$AA$4,1,R9)="","",INDEX(Lists!$H$4:$AA$4,1,R9)) | T9: =IF(S9="",-1,U9)-R9/1000000000 | U9: =IF(S9="",0,SUMIFS('Expense Log'!$I$5:$I$3000,'Expense Log'!$A$5:$A$3000,">="&$Q$3,'Expense Log'!$A$5:$A$3000,"<="&$Q$4,'Expense Log'!$C$5:$C$3000,S9,'Expense Log'!$J$5:$J$3000,$Q$5))
B10: Where the money went | H10: Top categories | P10: Prev month start | Q10: =IF($C$4="All time","",EDATE(Q3,-1)) | R10: 7 | S10: =IF(INDEX(Lists!$H$4:$AA$4,1,R10)="","",INDEX(Lists!$H$4:$AA$4,1,R10)) | T10: =IF(S10="",-1,U10)-R10/1000000000 | U10: =IF(S10="",0,SUMIFS('Expense Log'!$I$5:$I$3000,'Expense Log'!$A$5:$A$3000,">="&$Q$3,'Expense Log'!$A$5:$A$3000,"<="&$Q$4,'Expense Log'!$C$5:$C$3000,S10,'Expense Log'!$J$5:$J$3000,$Q$5))
B11: Category | D11: Spent | E11: % of total | F11: Budget | G11: Left / (over) | P11: Prev month end | Q11: =IF($C$4="All time","",Q3-1) | R11: 8 | S11: =IF(INDEX(Lists!$H$4:$AA$4,1,R11)="","",INDEX(Lists!$H$4:$AA$4,1,R11)) | T11: =IF(S11="",-1,U11)-R11/1000000000 | U11: =IF(S11="",0,SUMIFS('Expense Log'!$I$5:$I$3000,'Expense Log'!$A$5:$A$3000,">="&$Q$3,'Expense Log'!$A$5:$A$3000,"<="&$Q$4,'Expense Log'!$C$5:$C$3000,S11,'Expense Log'!$J$5:$J$3000,$Q$5))
B12: =INDEX($S$4:$S$23,V12) | D12: =IF(B12="","",INDEX($U$4:$U$23,V12)) | E12: =IF(OR(B12="",$Q$12=0),"",D12/$Q$12) | F12: =IF(B12="","",IF(INDEX(Lists!$H$5:$AA$5,1,V12)>0,INDEX(Lists!$H$5:$AA$5,1,V12)*$Q$6,"-")) | G12: =IF(OR(B12="",F12="-"),"",F12-D12) | P12: Total spent | Q12: =SUMIFS('Expense Log'!$I$5:$I$3000,'Expense Log'!$A$5:$A$3000,">="&Q3,'Expense Log'!$A$5:$A$3000,"<="&Q4,'Expense Log'!$J$5:$J$3000,Q5) | R12: 9 | S12: =IF(INDEX(Lists!$H$4:$AA$4,1,R12)="","",INDEX(Lists!$H$4:$AA$4,1,R12)) | T12: =IF(S12="",-1,U12)-R12/1000000000 | U12: =IF(S12="",0,SUMIFS('Expense Log'!$I$5:$I$3000,'Expense Log'!$A$5:$A$3000,">="&$Q$3,'Expense Log'!$A$5:$A$3000,"<="&$Q$4,'Expense Log'!$C$5:$C$3000,S12,'Expense Log'!$J$5:$J$3000,$Q$5)) | V12: =MATCH(LARGE($T$4:$T$23,ROWS($V$12:V12)),$T$4:$T$23,0)
B13: =INDEX($S$4:$S$23,V13) | D13: =IF(B13="","",INDEX($U$4:$U$23,V13)) | E13: =IF(OR(B13="",$Q$12=0),"",D13/$Q$12) | F13: =IF(B13="","",IF(INDEX(Lists!$H$5:$AA$5,1,V13)>0,INDEX(Lists!$H$5:$AA$5,1,V13)*$Q$6,"-")) | G13: =IF(OR(B13="",F13="-"),"",F13-D13) | P13: Prev month total | Q13: =IF(Q10="","",SUMIFS('Expense Log'!$I$5:$I$3000,'Expense Log'!$A$5:$A$3000,">="&Q10,'Expense Log'!$A$5:$A$3000,"<="&Q11,'Expense Log'!$J$5:$J$3000,Q5)) | R13: 10 | S13: =IF(INDEX(Lists!$H$4:$AA$4,1,R13)="","",INDEX(Lists!$H$4:$AA$4,1,R13)) | T13: =IF(S13="",-1,U13)-R13/1000000000 | U13: =IF(S13="",0,SUMIFS('Expense Log'!$I$5:$I$3000,'Expense Log'!$A$5:$A$3000,">="&$Q$3,'Expense Log'!$A$5:$A$3000,"<="&$Q$4,'Expense Log'!$C$5:$C$3000,S13,'Expense Log'!$J$5:$J$3000,$Q$5)) | V13: =MATCH(LARGE($T$4:$T$23,ROWS($V$12:V13)),$T$4:$T$23,0)
B14: =INDEX($S$4:$S$23,V14) | D14: =IF(B14="","",INDEX($U$4:$U$23,V14)) | E14: =IF(OR(B14="",$Q$12=0),"",D14/$Q$12) | F14: =IF(B14="","",IF(INDEX(Lists!$H$5:$AA$5,1,V14)>0,INDEX(Lists!$H$5:$AA$5,1,V14)*$Q$6,"-")) | G14: =IF(OR(B14="",F14="-"),"",F14-D14) | P14: Transactions | Q14: =COUNTIFS('Expense Log'!$A$5:$A$3000,">="&Q3,'Expense Log'!$A$5:$A$3000,"<="&Q4,'Expense Log'!$J$5:$J$3000,Q5) | R14: 11 | S14: =IF(INDEX(Lists!$H$4:$AA$4,1,R14)="","",INDEX(Lists!$H$4:$AA$4,1,R14)) | T14: =IF(S14="",-1,U14)-R14/1000000000 | U14: =IF(S14="",0,SUMIFS('Expense Log'!$I$5:$I$3000,'Expense Log'!$A$5:$A$3000,">="&$Q$3,'Expense Log'!$A$5:$A$3000,"<="&$Q$4,'Expense Log'!$C$5:$C$3000,S14,'Expense Log'!$J$5:$J$3000,$Q$5)) | V14: =MATCH(LARGE($T$4:$T$23,ROWS($V$12:V14)),$T$4:$T$23,0)
B15: =INDEX($S$4:$S$23,V15) | D15: =IF(B15="","",INDEX($U$4:$U$23,V15)) | E15: =IF(OR(B15="",$Q$12=0),"",D15/$Q$12) | F15: =IF(B15="","",IF(INDEX(Lists!$H$5:$AA$5,1,V15)>0,INDEX(Lists!$H$5:$AA$5,1,V15)*$Q$6,"-")) | G15: =IF(OR(B15="",F15="-"),"",F15-D15) | P15: Include one-off flag | Q15: =$G$4 | R15: 12 | S15: =IF(INDEX(Lists!$H$4:$AA$4,1,R15)="","",INDEX(Lists!$H$4:$AA$4,1,R15)) | T15: =IF(S15="",-1,U15)-R15/1000000000 | U15: =IF(S15="",0,SUMIFS('Expense Log'!$I$5:$I$3000,'Expense Log'!$A$5:$A$3000,">="&$Q$3,'Expense Log'!$A$5:$A$3000,"<="&$Q$4,'Expense Log'!$C$5:$C$3000,S15,'Expense Log'!$J$5:$J$3000,$Q$5)) | V15: =MATCH(LARGE($T$4:$T$23,ROWS($V$12:V15)),$T$4:$T$23,0)
B16: =INDEX($S$4:$S$23,V16) | D16: =IF(B16="","",INDEX($U$4:$U$23,V16)) | E16: =IF(OR(B16="",$Q$12=0),"",D16/$Q$12) | F16: =IF(B16="","",IF(INDEX(Lists!$H$5:$AA$5,1,V16)>0,INDEX(Lists!$H$5:$AA$5,1,V16)*$Q$6,"-")) | G16: =IF(OR(B16="",F16="-"),"",F16-D16) | P16: Drill-down category column | Q16: =IFERROR(MATCH($I$42,Lists!$H$4:$AA$4,0),0) | R16: 13 | S16: =IF(INDEX(Lists!$H$4:$AA$4,1,R16)="","",INDEX(Lists!$H$4:$AA$4,1,R16)) | T16: =IF(S16="",-1,U16)-R16/1000000000 | U16: =IF(S16="",0,SUMIFS('Expense Log'!$I$5:$I$3000,'Expense Log'!$A$5:$A$3000,">="&$Q$3,'Expense Log'!$A$5:$A$3000,"<="&$Q$4,'Expense Log'!$C$5:$C$3000,S16,'Expense Log'!$J$5:$J$3000,$Q$5)) | V16: =MATCH(LARGE($T$4:$T$23,ROWS($V$12:V16)),$T$4:$T$23,0)
B17: =INDEX($S$4:$S$23,V17) | D17: =IF(B17="","",INDEX($U$4:$U$23,V17)) | E17: =IF(OR(B17="",$Q$12=0),"",D17/$Q$12) | F17: =IF(B17="","",IF(INDEX(Lists!$H$5:$AA$5,1,V17)>0,INDEX(Lists!$H$5:$AA$5,1,V17)*$Q$6,"-")) | G17: =IF(OR(B17="",F17="-"),"",F17-D17) | P17: Drill-down category total | Q17: =SUMIFS('Expense Log'!$I$5:$I$3000,'Expense Log'!$C$5:$C$3000,$I$42,'Expense Log'!$A$5:$A$3000,">="&Q3,'Expense Log'!$A$5:$A$3000,"<="&Q4,'Expense Log'!$J$5:$J$3000,Q5) | R17: 14 | S17: =IF(INDEX(Lists!$H$4:$AA$4,1,R17)="","",INDEX(Lists!$H$4:$AA$4,1,R17)) | T17: =IF(S17="",-1,U17)-R17/1000000000 | U17: =IF(S17="",0,SUMIFS('Expense Log'!$I$5:$I$3000,'Expense Log'!$A$5:$A$3000,">="&$Q$3,'Expense Log'!$A$5:$A$3000,"<="&$Q$4,'Expense Log'!$C$5:$C$3000,S17,'Expense Log'!$J$5:$J$3000,$Q$5)) | V17: =MATCH(LARGE($T$4:$T$23,ROWS($V$12:V17)),$T$4:$T$23,0)
B18: =INDEX($S$4:$S$23,V18) | D18: =IF(B18="","",INDEX($U$4:$U$23,V18)) | E18: =IF(OR(B18="",$Q$12=0),"",D18/$Q$12) | F18: =IF(B18="","",IF(INDEX(Lists!$H$5:$AA$5,1,V18)>0,INDEX(Lists!$H$5:$AA$5,1,V18)*$Q$6,"-")) | G18: =IF(OR(B18="",F18="-"),"",F18-D18) | R18: 15 | S18: =IF(INDEX(Lists!$H$4:$AA$4,1,R18)="","",INDEX(Lists!$H$4:$AA$4,1,R18)) | T18: =IF(S18="",-1,U18)-R18/1000000000 | U18: =IF(S18="",0,SUMIFS('Expense Log'!$I$5:$I$3000,'Expense Log'!$A$5:$A$3000,">="&$Q$3,'Expense Log'!$A$5:$A$3000,"<="&$Q$4,'Expense Log'!$C$5:$C$3000,S18,'Expense Log'!$J$5:$J$3000,$Q$5)) | V18: =MATCH(LARGE($T$4:$T$23,ROWS($V$12:V18)),$T$4:$T$23,0)
B19: =INDEX($S$4:$S$23,V19) | D19: =IF(B19="","",INDEX($U$4:$U$23,V19)) | E19: =IF(OR(B19="",$Q$12=0),"",D19/$Q$12) | F19: =IF(B19="","",IF(INDEX(Lists!$H$5:$AA$5,1,V19)>0,INDEX(Lists!$H$5:$AA$5,1,V19)*$Q$6,"-")) | G19: =IF(OR(B19="",F19="-"),"",F19-D19) | R19: 16 | S19: =IF(INDEX(Lists!$H$4:$AA$4,1,R19)="","",INDEX(Lists!$H$4:$AA$4,1,R19)) | T19: =IF(S19="",-1,U19)-R19/1000000000 | U19: =IF(S19="",0,SUMIFS('Expense Log'!$I$5:$I$3000,'Expense Log'!$A$5:$A$3000,">="&$Q$3,'Expense Log'!$A$5:$A$3000,"<="&$Q$4,'Expense Log'!$C$5:$C$3000,S19,'Expense Log'!$J$5:$J$3000,$Q$5)) | V19: =MATCH(LARGE($T$4:$T$23,ROWS($V$12:V19)),$T$4:$T$23,0)
B20: =INDEX($S$4:$S$23,V20) | D20: =IF(B20="","",INDEX($U$4:$U$23,V20)) | E20: =IF(OR(B20="",$Q$12=0),"",D20/$Q$12) | F20: =IF(B20="","",IF(INDEX(Lists!$H$5:$AA$5,1,V20)>0,INDEX(Lists!$H$5:$AA$5,1,V20)*$Q$6,"-")) | G20: =IF(OR(B20="",F20="-"),"",F20-D20) | R20: 17 | S20: =IF(INDEX(Lists!$H$4:$AA$4,1,R20)="","",INDEX(Lists!$H$4:$AA$4,1,R20)) | T20: =IF(S20="",-1,U20)-R20/1000000000 | U20: =IF(S20="",0,SUMIFS('Expense Log'!$I$5:$I$3000,'Expense Log'!$A$5:$A$3000,">="&$Q$3,'Expense Log'!$A$5:$A$3000,"<="&$Q$4,'Expense Log'!$C$5:$C$3000,S20,'Expense Log'!$J$5:$J$3000,$Q$5)) | V20: =MATCH(LARGE($T$4:$T$23,ROWS($V$12:V20)),$T$4:$T$23,0)
B21: =INDEX($S$4:$S$23,V21) | D21: =IF(B21="","",INDEX($U$4:$U$23,V21)) | E21: =IF(OR(B21="",$Q$12=0),"",D21/$Q$12) | F21: =IF(B21="","",IF(INDEX(Lists!$H$5:$AA$5,1,V21)>0,INDEX(Lists!$H$5:$AA$5,1,V21)*$Q$6,"-")) | G21: =IF(OR(B21="",F21="-"),"",F21-D21) | R21: 18 | S21: =IF(INDEX(Lists!$H$4:$AA$4,1,R21)="","",INDEX(Lists!$H$4:$AA$4,1,R21)) | T21: =IF(S21="",-1,U21)-R21/1000000000 | U21: =IF(S21="",0,SUMIFS('Expense Log'!$I$5:$I$3000,'Expense Log'!$A$5:$A$3000,">="&$Q$3,'Expense Log'!$A$5:$A$3000,"<="&$Q$4,'Expense Log'!$C$5:$C$3000,S21,'Expense Log'!$J$5:$J$3000,$Q$5)) | V21: =MATCH(LARGE($T$4:$T$23,ROWS($V$12:V21)),$T$4:$T$23,0)
B22: =INDEX($S$4:$S$23,V22) | D22: =IF(B22="","",INDEX($U$4:$U$23,V22)) | E22: =IF(OR(B22="",$Q$12=0),"",D22/$Q$12) | F22: =IF(B22="","",IF(INDEX(Lists!$H$5:$AA$5,1,V22)>0,INDEX(Lists!$H$5:$AA$5,1,V22)*$Q$6,"-")) | G22: =IF(OR(B22="",F22="-"),"",F22-D22) | R22: 19 | S22: =IF(INDEX(Lists!$H$4:$AA$4,1,R22)="","",INDEX(Lists!$H$4:$AA$4,1,R22)) | T22: =IF(S22="",-1,U22)-R22/1000000000 | U22: =IF(S22="",0,SUMIFS('Expense Log'!$I$5:$I$3000,'Expense Log'!$A$5:$A$3000,">="&$Q$3,'Expense Log'!$A$5:$A$3000,"<="&$Q$4,'Expense Log'!$C$5:$C$3000,S22,'Expense Log'!$J$5:$J$3000,$Q$5)) | V22: =MATCH(LARGE($T$4:$T$23,ROWS($V$12:V22)),$T$4:$T$23,0)
B23: =INDEX($S$4:$S$23,V23) | D23: =IF(B23="","",INDEX($U$4:$U$23,V23)) | E23: =IF(OR(B23="",$Q$12=0),"",D23/$Q$12) | F23: =IF(B23="","",IF(INDEX(Lists!$H$5:$AA$5,1,V23)>0,INDEX(Lists!$H$5:$AA$5,1,V23)*$Q$6,"-")) | G23: =IF(OR(B23="",F23="-"),"",F23-D23) | R23: 20 | S23: =IF(INDEX(Lists!$H$4:$AA$4,1,R23)="","",INDEX(Lists!$H$4:$AA$4,1,R23)) | T23: =IF(S23="",-1,U23)-R23/1000000000 | U23: =IF(S23="",0,SUMIFS('Expense Log'!$I$5:$I$3000,'Expense Log'!$A$5:$A$3000,">="&$Q$3,'Expense Log'!$A$5:$A$3000,"<="&$Q$4,'Expense Log'!$C$5:$C$3000,S23,'Expense Log'!$J$5:$J$3000,$Q$5)) | V23: =MATCH(LARGE($T$4:$T$23,ROWS($V$12:V23)),$T$4:$T$23,0)
B24: =INDEX($S$4:$S$23,V24) | D24: =IF(B24="","",INDEX($U$4:$U$23,V24)) | E24: =IF(OR(B24="",$Q$12=0),"",D24/$Q$12) | F24: =IF(B24="","",IF(INDEX(Lists!$H$5:$AA$5,1,V24)>0,INDEX(Lists!$H$5:$AA$5,1,V24)*$Q$6,"-")) | G24: =IF(OR(B24="",F24="-"),"",F24-D24) | V24: =MATCH(LARGE($T$4:$T$23,ROWS($V$12:V24)),$T$4:$T$23,0)
B25: =INDEX($S$4:$S$23,V25) | D25: =IF(B25="","",INDEX($U$4:$U$23,V25)) | E25: =IF(OR(B25="",$Q$12=0),"",D25/$Q$12) | F25: =IF(B25="","",IF(INDEX(Lists!$H$5:$AA$5,1,V25)>0,INDEX(Lists!$H$5:$AA$5,1,V25)*$Q$6,"-")) | G25: =IF(OR(B25="",F25="-"),"",F25-D25) | V25: =MATCH(LARGE($T$4:$T$23,ROWS($V$12:V25)),$T$4:$T$23,0)
B26: =INDEX($S$4:$S$23,V26) | D26: =IF(B26="","",INDEX($U$4:$U$23,V26)) | E26: =IF(OR(B26="",$Q$12=0),"",D26/$Q$12) | F26: =IF(B26="","",IF(INDEX(Lists!$H$5:$AA$5,1,V26)>0,INDEX(Lists!$H$5:$AA$5,1,V26)*$Q$6,"-")) | G26: =IF(OR(B26="",F26="-"),"",F26-D26) | V26: =MATCH(LARGE($T$4:$T$23,ROWS($V$12:V26)),$T$4:$T$23,0)
B27: Total | D27: =SUM(D12:D26) | E27: =IF($Q$12=0,"",SUM(E12:E26)) | F27: =IF(COUNT(F12:F26)=0,"-",SUM(F12:F26))
B28: =IF(ABS($Q$12-D27)>0.005,"Warning: "&TEXT($Q$12-D27,"$#,##0.00")&" is logged under a category that is not on the Lists sheet","")
B30: Settle up (all costs, incl. one-offs) | H30: Biggest transactions in period
B31: Person | D31: Paid | E31: Their share | F31: Net (paid - share) | H31: Date | I31: Merchant | K31: Category | M31: Amount
B32: =Lists!$A$5 | D32: =SUMIFS('Expense Log'!$I$5:$I$3000,'Expense Log'!$F$5:$F$3000,B32,'Expense Log'!$A$5:$A$3000,">="&$Q$3,'Expense Log'!$A$5:$A$3000,"<="&$Q$4) | E32: =SUMIFS('Expense Log'!$M$5:$M$3000,'Expense Log'!$A$5:$A$3000,">="&$Q$3,'Expense Log'!$A$5:$A$3000,"<="&$Q$4) | F32: =D32-E32 | H32: =IF($W32="","",INDEX('Expense Log'!$A$5:$A$3000,$W32)) | I32: =IF($W32="","",INDEX('Expense Log'!$B$5:$B$3000,$W32)) | K32: =IF($W32="","",INDEX('Expense Log'!$C$5:$C$3000,$W32)) | M32: =IF($W32="","",INDEX('Expense Log'!$I$5:$I$3000,$W32)) | W32: =IFERROR(MATCH(LARGE('Expense Log'!$Q$5:$Q$3000,ROWS(W$32:W32)),'Expense Log'!$Q$5:$Q$3000,0),"")
B33: =Lists!$A$6 | D33: =SUMIFS('Expense Log'!$I$5:$I$3000,'Expense Log'!$F$5:$F$3000,B33,'Expense Log'!$A$5:$A$3000,">="&$Q$3,'Expense Log'!$A$5:$A$3000,"<="&$Q$4) | E33: =SUMIFS('Expense Log'!$N$5:$N$3000,'Expense Log'!$A$5:$A$3000,">="&$Q$3,'Expense Log'!$A$5:$A$3000,"<="&$Q$4) | F33: =D33-E33 | H33: =IF($W33="","",INDEX('Expense Log'!$A$5:$A$3000,$W33)) | I33: =IF($W33="","",INDEX('Expense Log'!$B$5:$B$3000,$W33)) | K33: =IF($W33="","",INDEX('Expense Log'!$C$5:$C$3000,$W33)) | M33: =IF($W33="","",INDEX('Expense Log'!$I$5:$I$3000,$W33)) | W33: =IFERROR(MATCH(LARGE('Expense Log'!$Q$5:$Q$3000,ROWS(W$32:W33)),'Expense Log'!$Q$5:$Q$3000,0),"")
B34: =IF(ABS(F32)<0.005,"All square - nobody owes anything",IF(F32>0,B33&" owes "&B32&" "&TEXT(F32,"$#,##0.00"),B32&" owes "&B33&" "&TEXT(-F32,"$#,##0.00"))) | H34: =IF($W34="","",INDEX('Expense Log'!$A$5:$A$3000,$W34)) | I34: =IF($W34="","",INDEX('Expense Log'!$B$5:$B$3000,$W34)) | K34: =IF($W34="","",INDEX('Expense Log'!$C$5:$C$3000,$W34)) | M34: =IF($W34="","",INDEX('Expense Log'!$I$5:$I$3000,$W34)) | W34: =IFERROR(MATCH(LARGE('Expense Log'!$Q$5:$Q$3000,ROWS(W$32:W34)),'Expense Log'!$Q$5:$Q$3000,0),"")
H35: =IF($W35="","",INDEX('Expense Log'!$A$5:$A$3000,$W35)) | I35: =IF($W35="","",INDEX('Expense Log'!$B$5:$B$3000,$W35)) | K35: =IF($W35="","",INDEX('Expense Log'!$C$5:$C$3000,$W35)) | M35: =IF($W35="","",INDEX('Expense Log'!$I$5:$I$3000,$W35)) | W35: =IFERROR(MATCH(LARGE('Expense Log'!$Q$5:$Q$3000,ROWS(W$32:W35)),'Expense Log'!$Q$5:$Q$3000,0),"")
B36: Split type | D36: Amount | E36: % of total | H36: =IF($W36="","",INDEX('Expense Log'!$A$5:$A$3000,$W36)) | I36: =IF($W36="","",INDEX('Expense Log'!$B$5:$B$3000,$W36)) | K36: =IF($W36="","",INDEX('Expense Log'!$C$5:$C$3000,$W36)) | M36: =IF($W36="","",INDEX('Expense Log'!$I$5:$I$3000,$W36)) | W36: =IFERROR(MATCH(LARGE('Expense Log'!$Q$5:$Q$3000,ROWS(W$32:W36)),'Expense Log'!$Q$5:$Q$3000,0),"")
B37: =Lists!$B$5 | D37: =SUMIFS('Expense Log'!$I$5:$I$3000,'Expense Log'!$G$5:$G$3000,B37,'Expense Log'!$A$5:$A$3000,">="&$Q$3,'Expense Log'!$A$5:$A$3000,"<="&$Q$4) | E37: =IF(SUM($D$37:$D$39)=0,"",D37/SUM($D$37:$D$39)) | H37: =IF($W37="","",INDEX('Expense Log'!$A$5:$A$3000,$W37)) | I37: =IF($W37="","",INDEX('Expense Log'!$B$5:$B$3000,$W37)) | K37: =IF($W37="","",INDEX('Expense Log'!$C$5:$C$3000,$W37)) | M37: =IF($W37="","",INDEX('Expense Log'!$I$5:$I$3000,$W37)) | W37: =IFERROR(MATCH(LARGE('Expense Log'!$Q$5:$Q$3000,ROWS(W$32:W37)),'Expense Log'!$Q$5:$Q$3000,0),"")
B38: =Lists!$B$6 | D38: =SUMIFS('Expense Log'!$I$5:$I$3000,'Expense Log'!$G$5:$G$3000,B38,'Expense Log'!$A$5:$A$3000,">="&$Q$3,'Expense Log'!$A$5:$A$3000,"<="&$Q$4) | E38: =IF(SUM($D$37:$D$39)=0,"",D38/SUM($D$37:$D$39)) | H38: =IF($W38="","",INDEX('Expense Log'!$A$5:$A$3000,$W38)) | I38: =IF($W38="","",INDEX('Expense Log'!$B$5:$B$3000,$W38)) | K38: =IF($W38="","",INDEX('Expense Log'!$C$5:$C$3000,$W38)) | M38: =IF($W38="","",INDEX('Expense Log'!$I$5:$I$3000,$W38)) | W38: =IFERROR(MATCH(LARGE('Expense Log'!$Q$5:$Q$3000,ROWS(W$32:W38)),'Expense Log'!$Q$5:$Q$3000,0),"")
B39: =Lists!$B$7 | D39: =SUMIFS('Expense Log'!$I$5:$I$3000,'Expense Log'!$G$5:$G$3000,B39,'Expense Log'!$A$5:$A$3000,">="&$Q$3,'Expense Log'!$A$5:$A$3000,"<="&$Q$4) | E39: =IF(SUM($D$37:$D$39)=0,"",D39/SUM($D$37:$D$39)) | H39: =IF($W39="","",INDEX('Expense Log'!$A$5:$A$3000,$W39)) | I39: =IF($W39="","",INDEX('Expense Log'!$B$5:$B$3000,$W39)) | K39: =IF($W39="","",INDEX('Expense Log'!$C$5:$C$3000,$W39)) | M39: =IF($W39="","",INDEX('Expense Log'!$I$5:$I$3000,$W39)) | W39: =IFERROR(MATCH(LARGE('Expense Log'!$Q$5:$Q$3000,ROWS(W$32:W39)),'Expense Log'!$Q$5:$Q$3000,0),"")
B41: Monthly trend (last 12 months) | H41: Category drill-down
H42: Category: | I42: =Lists!$H$4
...

Sheet Expense Log
A1: Couples Monthly Expense Log
A2: Type in the columns with navy headers. Category, Sub-Category, Expense Type, Paid By, Split Type, Payment Method and One-off? are dropdowns (managed on the Lists sheet). Pick the Main Category first - the Sub-Category list then filters itself. Pasting a bank CSV? Paste into Date, Description and Amount, then pick the rest.
A3: Navy header = you type | Grey header (L:O) = automatic, don't edit | Row turns red = something is missing, see Status
A4: Date | B4: Merchant / Description | C4: Main Category | D4: Sub-Category | E4: Expense Type | F4: Paid By | G4: Split Type | H4: Payment Method | I4: Amount ($) | J4: One-off? | K4: Notes | L4: Month | M4: =Lists!$A$5&"'s Share ($)" | N4: =Lists!$A$6&"'s Share ($)" | O4: Status | P4: Rank key | Q4: Period key
L5: =IF(A5="","",DATE(YEAR(A5),MONTH(A5),1)) | M5: =IF(OR(A5="",NOT(ISNUMBER(I5))),"",IF(G5=Lists!$B$5,I5/2,IF(G5=Lists!$B$6,I5,0))) | N5: =IF(OR(A5="",NOT(ISNUMBER(I5))),"",IF(G5=Lists!$B$5,I5/2,IF(G5=Lists!$B$7,I5,0))) | O5: =IF(COUNTA(A5:K5)=0,"",IF(OR(A5="",B5="",C5="",D5="",E5="",F5="",G5="",NOT(ISNUMBER(I5))),"Incomplete",IF(COUNTIF(Lists!$H$4:$AA$4,C5)=0,"Check category",IF(COUNTIF(INDEX(Lists!$H$6:$AA$45,0,MATCH(C5,Lists!$H$4:$AA$4,0)),D5)=0,"Check sub-category","OK")))) | P5: =IF(ISNUMBER(I5),I5+ROW()/10000000,"") | Q5: =IF(AND(ISNUMBER(P5),ISNUMBER(A5)),IF(AND(A5>=Dashboard!$Q$3,A5<=Dashboard!$Q$4,OR(J5<>"Yes",Dashboard!$Q$15="Yes")),P5,""),"")
L6: =IF(A6="","",DATE(YEAR(A6),MONTH(A6),1)) | M6: =IF(OR(A6="",NOT(ISNUMBER(I6))),"",IF(G6=Lists!$B$5,I6/2,IF(G6=Lists!$B$6,I6,0))) | N6: =IF(OR(A6="",NOT(ISNUMBER(I6))),"",IF(G6=Lists!$B$5,I6/2,IF(G6=Lists!$B$7,I6,0))) | O6: =IF(COUNTA(A6:K6)=0,"",IF(OR(A6="",B6="",C6="",D6="",E6="",F6="",G6="",NOT(ISNUMBER(I6))),"Incomplete",IF(COUNTIF(Lists!$H$4:$AA$4,C6)=0,"Check category",IF(COUNTIF(INDEX(Lists!$H$6:$AA$45,0,MATCH(C6,Lists!$H$4:$AA$4,0)),D6)=0,"Check sub-category","OK")))) | P6: =IF(ISNUMBER(I6),I6+ROW()/10000000,"") | Q6: =IF(AND(ISNUMBER(P6),ISNUMBER(A6)),IF(AND(A6>=Dashboard!$Q$3,A6<=Dashboard!$Q$4,OR(J6<>"Yes",Dashboard!$Q$15="Yes")),P6,""),"")
L7: =IF(A7="","",DATE(YEAR(A7),MONTH(A7),1)) | M7: =IF(OR(A7="",NOT(ISNUMBER(I7))),"",IF(G7=Lists!$B$5,I7/2,IF(G7=Lists!$B$6,I7,0))) | N7: =IF(OR(A7="",NOT(ISNUMBER(I7))),"",IF(G7=Lists!$B$5,I7/2,IF(G7=Lists!$B$7,I7,0))) | O7: =IF(COUNTA(A7:K7)=0,"",IF(OR(A7="",B7="",C7="",D7="",E7="",F7="",G7="",NOT(ISNUMBER(I7))),"Incomplete",IF(COUNTIF(Lists!$H$4:$AA$4,C7)=0,"Check category",IF(COUNTIF(INDEX(Lists!$H$6:$AA$45,0,MATCH(C7,Lists!$H$4:$AA$4,0)),D7)=0,"Check sub-category","OK")))) | P7: =IF(ISNUMBER(I7),I7+ROW()/10000000,"") | Q7: =IF(AND(ISNUMBER(P7),ISNUMBER(A7)),IF(AND(A7>=Dashboard!$Q$3,A7<=Dashboard!$Q$4,OR(J7<>"Yes",Dashboard!$Q$15="Yes")),P7,""),"")
L8: =IF(A8="","",DATE(YEAR(A8),MONTH(A8),1)) | M8: =IF(OR(A8="",NOT(ISNUMBER(I8))),"",IF(G8=Lists!$B$5,I8/2,IF(G8=Lists!$B$6,I8,0))) | N8: =IF(OR(A8="",NOT(ISNUMBER(I8))),"",IF(G8=Lists!$B$5,I8/2,IF(G8=Lists!$B$7,I8,0))) | O8: =IF(COUNTA(A8:K8)=0,"",IF(OR(A8="",B8="",C8="",D8="",E8="",F8="",G8="",NOT(ISNUMBER(I8))),"Incomplete",IF(COUNTIF(Lists!$H$4:$AA$4,C8)=0,"Check category",IF(COUNTIF(INDEX(Lists!$H$6:$AA$45,0,MATCH(C8,Lists!$H$4:$AA$4,0)),D8)=0,"Check sub-category","OK")))) | P8: =IF(ISNUMBER(I8),I8+ROW()/10000000,"") | Q8: =IF(AND(ISNUMBER(P8),ISNUMBER(A8)),IF(AND(A8>=Dashboard!$Q$3,A8<=Dashboard!$Q$4,OR(J8<>"Yes",Dashboard!$Q$15="Yes")),P8,""),"")
L9: =IF(A9="","",DATE(YEAR(A9),MONTH(A9),1)) | M9: =IF(OR(A9="",NOT(ISNUMBER(I9))),"",IF(G9=Lists!$B$5,I9/2,IF(G9=Lists!$B$6,I9,0))) | N9: =IF(OR(A9="",NOT(ISNUMBER(I9))),"",IF(G9=Lists!$B$5,I9/2,IF(G9=Lists!$B$7,I9,0))) | O9: =IF(COUNTA(A9:K9)=0,"",IF(OR(A9="",B9="",C9="",D9="",E9="",F9="",G9="",NOT(ISNUMBER(I9))),"Incomplete",IF(COUNTIF(Lists!$H$4:$AA$4,C9)=0,"Check category",IF(COUNTIF(INDEX(Lists!$H$6:$AA$45,0,MATCH(C9,Lists!$H$4:$AA$4,0)),D9)=0,"Check sub-category","OK")))) | P9: =IF(ISNUMBER(I9),I9+ROW()/10000000,"") | Q9: =IF(AND(ISNUMBER(P9),ISNUMBER(A9)),IF(AND(A9>=Dashboard!$Q$3,A9<=Dashboard!$Q$4,OR(J9<>"Yes",Dashboard!$Q$15="Yes")),P9,""),"")
L10: =IF(A10="","",DATE(YEAR(A10),MONTH(A10),1)) | M10: =IF(OR(A10="",NOT(ISNUMBER(I10))),"",IF(G10=Lists!$B$5,I10/2,IF(G10=Lists!$B$6,I10,0))) | N10: =IF(OR(A10="",NOT(ISNUMBER(I10))),"",IF(G10=Lists!$B$5,I10/2,IF(G10=Lists!$B$7,I10,0))) | O10: =IF(COUNTA(A10:K10)=0,"",IF(OR(A10="",B10="",C10="",D10="",E10="",F10="",G10="",NOT(ISNUMBER(I10))),"Incomplete",IF(COUNTIF(Lists!$H$4:$AA$4,C10)=0,"Check category",IF(COUNTIF(INDEX(Lists!$H$6:$AA$45,0,MATCH(C10,Lists!$H$4:$AA$4,0)),D10)=0,"Check sub-category","OK")))) | P10: =IF(ISNUMBER(I10),I10+ROW()/10000000,"") | Q10: =IF(AND(ISNUMBER(P10),ISNUMBER(A10)),IF(AND(A10>=Dashboard!$Q$3,A10<=Dashboard!$Q$4,OR(J10<>"Yes",Dashboard!$Q$15="Yes")),P10,""),"")
L11: =IF(A11="","",DATE(YEAR(A11),MONTH(A11),1)) | M11: =IF(OR(A11="",NOT(ISNUMBER(I11))),"",IF(G11=Lists!$B$5,I11/2,IF(G11=Lists!$B$6,I11,0))) | N11: =IF(OR(A11="",NOT(ISNUMBER(I11))),"",IF(G11=Lists!$B$5,I11/2,IF(G11=Lists!$B$7,I11,0))) | O11: =IF(COUNTA(A11:K11)=0,"",IF(OR(A11="",B11="",C11="",D11="",E11="",F11="",G11="",NOT(ISNUMBER(I11))),"Incomplete",IF(COUNTIF(Lists!$H$4:$AA$4,C11)=0,"Check category",IF(COUNTIF(INDEX(Lists!$H$6:$AA$45,0,MATCH(C11,Lists!$H$4:$AA$4,0)),D11)=0,"Check sub-category","OK")))) | P11: =IF(ISNUMBER(I11),I11+ROW()/10000000,"") | Q11: =IF(AND(ISNUMBER(P11),ISNUMBER(A11)),IF(AND(A11>=Dashboard!$Q$3,A11<=Dashboard!$Q$4,OR(J11<>"Yes",Dashboard!$Q$15="Yes")),P11,""),"")
L12: =IF(A12="","",DATE(YEAR(A12),MONTH(A12),1)) | M12: =IF(OR(A12="",NOT(ISNUMBER(I12))),"",IF(G12=Lists!$B$5,I12/2,IF(G12=Lists!$B$6,I12,0))) | N12: =IF(OR(A12="",NOT(ISNUMBER(I12))),"",IF(G12=Lists!$B$5,I12/2,IF(G12=Lists!$B$7,I12,0))) | O12: =IF(COUNTA(A12:K12)=0,"",IF(OR(A12="",B12="",C12="",D12="",E12="",F12="",G12="",NOT(ISNUMBER(I12))),"Incomplete",IF(COUNTIF(Lists!$H$4:$AA$4,C12)=0,"Check category",IF(COUNTIF(INDEX(Lists!$H$6:$AA$45,0,MATCH(C12,Lists!$H$4:$AA$4,0)),D12)=0,"Check sub-category","OK")))) | P12: =IF(ISNUMBER(I12),I12+ROW()/10000000,"") | Q12: =IF(AND(ISNUMBER(P12),ISNUMBER(A12)),IF(AND(A12>=Dashboard!$Q$3,A12<=Dashboard!$Q$4,OR(J12<>"Yes",Dashboard!$Q$15="Yes")),P12,""),"")
L13: =IF(A13="","",DATE(YEAR(A13),MONTH(A13),1)) | M13: =IF(OR(A13="",NOT(ISNUMBER(I13))),"",IF(G13=Lists!$B$5,I13/2,IF(G13=Lists!$B$6,I13,0))) | N13: =IF(OR(A13="",NOT(ISNUMBER(I13))),"",IF(G13=Lists!$B$5,I13/2,IF(G13=Lists!$B$7,I13,0))) | O13: =IF(COUNTA(A13:K13)=0,"",IF(OR(A13="",B13="",C13="",D13="",E13="",F13="",G13="",NOT(ISNUMBER(I13))),"Incomplete",IF(COUNTIF(Lists!$H$4:$AA$4,C13)=0,"Check category",IF(COUNTIF(INDEX(Lists!$H$6:$AA$45,0,MATCH(C13,Lists!$H$4:$AA$4,0)),D13)=0,"Check sub-category","OK")))) | P13: =IF(ISNUMBER(I13),I13+ROW()/10000000,"") | Q13: =IF(AND(ISNUMBER(P13),ISNUMBER(A13)),IF(AND(A13>=Dashboard!$Q$3,A13<=Dashboard!$Q$4,OR(J13<>"Yes",Dashboard!$Q$15="Yes")),P13,""),"")
L14: =IF(A14="","",DATE(YEAR(A14),MONTH(A14),1)) | M14: =IF(OR(A14="",NOT(ISNUMBER(I14))),"",IF(G14=Lists!$B$5,I14/2,IF(G14=Lists!$B$6,I14,0))) | N14: =IF(OR(A14="",NOT(ISNUMBER(I14))),"",IF(G14=Lists!$B$5,I14/2,IF(G14=Lists!$B$7,I14,0))) | O14: =IF(COUNTA(A14:K14)=0,"",IF(OR(A14="",B14="",C14="",D14="",E14="",F14="",G14="",NOT(ISNUMBER(I14))),"Incomplete",IF(COUNTIF(Lists!$H$4:$AA$4,C14)=0,"Check category",IF(COUNTIF(INDEX(Lists!$H$6:$AA$45,0,MATCH(C14,Lists!$H$4:$AA$4,0)),D14)=0,"Check sub-category","OK")))) | P14: =IF(ISNUMBER(I14),I14+ROW()/10000000,"") | Q14: =IF(AND(ISNUMBER(P14),ISNUMBER(A14)),IF(AND(A14>=Dashboard!$Q$3,A14<=Dashboard!$Q$4,OR(J14<>"Yes",Dashboard!$Q$15="Yes")),P14,""),"")
L15: =IF(A15="","",DATE(YEAR(A15),MONTH(A15),1)) | M15: =IF(OR(A15="",NOT(ISNUMBER(I15))),"",IF(G15=Lists!$B$5,I15/2,IF(G15=Lists!$B$6,I15,0))) | N15: =IF(OR(A15="",NOT(ISNUMBER(I15))),"",IF(G15=Lists!$B$5,I15/2,IF(G15=Lists!$B$7,I15,0))) | O15: =IF(COUNTA(A15:K15)=0,"",IF(OR(A15="",B15="",C15="",D15="",E15="",F15="",G15="",NOT(ISNUMBER(I15))),"Incomplete",IF(COUNTIF(Lists!$H$4:$AA$4,C15)=0,"Check category",IF(COUNTIF(INDEX(Lists!$H$6:$AA$45,0,MATCH(C15,Lists!$H$4:$AA$4,0)),D15)=0,"Check sub-category","OK")))) | P15: =IF(ISNUMBER(I15),I15+ROW()/10000000,"") | Q15: =IF(AND(ISNUMBER(P15),ISNUMBER(A15)),IF(AND(A15>=Dashboard!$Q$3,A15<=Dashboard!$Q$4,OR(J15<>"Yes",Dashboard!$Q$15="Yes")),P15,""),"")
L16: =IF(A16="","",DATE(YEAR(A16),MONTH(A16),1)) | M16: =IF(OR(A16="",NOT(ISNUMBER(I16))),"",IF(G16=Lists!$B$5,I16/2,IF(G16=Lists!$B$6,I16,0))) | N16: =IF(OR(A16="",NOT(ISNUMBER(I16))),"",IF(G16=Lists!$B$5,I16/2,IF(G16=Lists!$B$7,I16,0))) | O16: =IF(COUNTA(A16:K16)=0,"",IF(OR(A16="",B16="",C16="",D16="",E16="",F16="",G16="",NOT(ISNUMBER(I16))),"Incomplete",IF(COUNTIF(Lists!$H$4:$AA$4,C16)=0,"Check category",IF(COUNTIF(INDEX(Lists!$H$6:$AA$45,0,MATCH(C16,Lists!$H$4:$AA$4,0)),D16)=0,"Check sub-category","OK")))) | P16: =IF(ISNUMBER(I16),I16+ROW()/10000000,"") | Q16: =IF(AND(ISNUMBER(P16),ISNUMBER(A16)),IF(AND(A16>=Dashboard!$Q$3,A16<=Dashboard!$Q$4,OR(J16<>"Yes",Dashboard!$Q$15="Yes")),P16,""),"")
... L3000: =IF(A3000="","",DATE(YEAR(A3000),MONTH(A3000),1)) | M3000: =IF(OR(A3000="",NOT(ISNUMBER(I3000))),"",IF(G3000=Lists!$B$5,I3000/2,IF(G3000=Lists!$B$6,I3000,0))) | N3000: =IF(OR(A3000="",NOT(ISNUMBER(I3000))),"",IF(G3000=Lists!$B$5,I3000/2,IF(G3000=Lists!$B$7,I3000,0))) | O3000: =IF(COUNTA(A3000:K3000)=0,"",IF(OR(A3000="",B3000="",C3000="",D3000="",E3000="",F3000="",G3000="",NOT(ISNUMBER(I3000))),"Incomplete",IF(COUNTIF(Lists!$H$4:$AA$4,C3000)=0,"Check category",IF(COUNTIF(INDEX(Lists!$H$6:$AA$45,0,MATCH(C3000,Lists!$H$4:$AA$4,0)),D3000)=0,"Check sub-category","OK")))) | P3000: =IF(ISNUMBER(I3000),I3000+ROW()/10000000,"") | Q3000: =IF(AND(ISNUMBER(P3000),ISNUMBER(A3000)),IF(AND(A3000>=Dashboard!$Q$3,A3000<=Dashboard!$Q$4,OR(J3000<>"Yes",Dashboard!$Q$15="Yes")),P3000,""),"")

Sheet Monthly Summary
A1: Monthly Summary - spend by category and month
A2: Fully automatic. New months and new categories appear on their own as you log expenses.
A3: Category | B3: =IF(COUNT('Expense Log'!$A$5:$A$3000)=0,"",DATE(YEAR(MIN('Expense Log'!$A$5:$A$3000)),MONTH(MIN('Expense Log'!$A$5:$A$3000)),1)) | C3: =IF(B3="","",IF(EDATE(B3,1)>MAX('Expense Log'!$L$5:$L$3000),"",EDATE(B3,1))) | D3: =IF(C3="","",IF(EDATE(C3,1)>MAX('Expense Log'!$L$5:$L$3000),"",EDATE(C3,1))) | E3: =IF(D3="","",IF(EDATE(D3,1)>MAX('Expense Log'!$L$5:$L$3000),"",EDATE(D3,1))) | F3: =IF(E3="","",IF(EDATE(E3,1)>MAX('Expense Log'!$L$5:$L$3000),"",EDATE(E3,1))) | G3: =IF(F3="","",IF(EDATE(F3,1)>MAX('Expense Log'!$L$5:$L$3000),"",EDATE(F3,1))) | H3: =IF(G3="","",IF(EDATE(G3,1)>MAX('Expense Log'!$L$5:$L$3000),"",EDATE(G3,1))) | I3: =IF(H3="","",IF(EDATE(H3,1)>MAX('Expense Log'!$L$5:$L$3000),"",EDATE(H3,1))) | J3: =IF(I3="","",IF(EDATE(I3,1)>MAX('Expense Log'!$L$5:$L$3000),"",EDATE(I3,1))) | ... Y3: =IF(X3="","",IF(EDATE(X3,1)>MAX('Expense Log'!$L$5:$L$3000),"",EDATE(X3,1))) | Z3: Total | AB3: Month list (Dashboard dropdown)
A4: =IF(INDEX(Lists!$H$4:$AA$4,1,1)="","",INDEX(Lists!$H$4:$AA$4,1,1)) | B4: =IF(OR($A4="",B$3=""),"",SUMIFS('Expense Log'!$I$5:$I$3000,'Expense Log'!$L$5:$L$3000,B$3,'Expense Log'!$C$5:$C$3000,$A4)) | C4: =IF(OR($A4="",C$3=""),"",SUMIFS('Expense Log'!$I$5:$I$3000,'Expense Log'!$L$5:$L$3000,C$3,'Expense Log'!$C$5:$C$3000,$A4)) | D4: =IF(OR($A4="",D$3=""),"",SUMIFS('Expense Log'!$I$5:$I$3000,'Expense Log'!$L$5:$L$3000,D$3,'Expense Log'!$C$5:$C$3000,$A4)) | E4: =IF(OR($A4="",E$3=""),"",SUMIFS('Expense Log'!$I$5:$I$3000,'Expense Log'!$L$5:$L$3000,E$3,'Expense Log'!$C$5:$C$3000,$A4)) | F4: =IF(OR($A4="",F$3=""),"",SUMIFS('Expense Log'!$I$5:$I$3000,'Expense Log'!$L$5:$L$3000,F$3,'Expense Log'!$C$5:$C$3000,$A4)) | G4: =IF(OR($A4="",G$3=""),"",SUMIFS('Expense Log'!$I$5:$I$3000,'Expense Log'!$L$5:$L$3000,G$3,'Expense Log'!$C$5:$C$3000,$A4)) | H4: =IF(OR($A4="",H$3=""),"",SUMIFS('Expense Log'!$I$5:$I$3000,'Expense Log'!$L$5:$L$3000,H$3,'Expense Log'!$C$5:$C$3000,$A4)) | I4: =IF(OR($A4="",I$3=""),"",SUMIFS('Expense Log'!$I$5:$I$3000,'Expense Log'!$L$5:$L$3000,I$3,'Expense Log'!$C$5:$C$3000,$A4)) | ... Y4: =IF(OR($A4="",Y$3=""),"",SUMIFS('Expense Log'!$I$5:$I$3000,'Expense Log'!$L$5:$L$3000,Y$3,'Expense Log'!$C$5:$C$3000,$A4)) | Z4: =IF($A4="","",SUM(B4:Y4)) | AB4: All time
A5: =IF(INDEX(Lists!$H$4:$AA$4,1,2)="","",INDEX(Lists!$H$4:$AA$4,1,2)) | B5: =IF(OR($A5="",B$3=""),"",SUMIFS('Expense Log'!$I$5:$I$3000,'Expense Log'!$L$5:$L$3000,B$3,'Expense Log'!$C$5:$C$3000,$A5)) | C5: =IF(OR($A5="",C$3=""),"",SUMIFS('Expense Log'!$I$5:$I$3000,'Expense Log'!$L$5:$L$3000,C$3,'Expense Log'!$C$5:$C$3000,$A5)) | D5: =IF(OR($A5="",D$3=""),"",SUMIFS('Expense Log'!$I$5:$I$3000,'Expense Log'!$L$5:$L$3000,D$3,'Expense Log'!$C$5:$C$3000,$A5)) | E5: =IF(OR($A5="",E$3=""),"",SUMIFS('Expense Log'!$I$5:$I$3000,'Expense Log'!$L$5:$L$3000,E$3,'Expense Log'!$C$5:$C$3000,$A5)) | F5: =IF(OR($A5="",F$3=""),"",SUMIFS('Expense Log'!$I$5:$I$3000,'Expense Log'!$L$5:$L$3000,F$3,'Expense Log'!$C$5:$C$3000,$A5)) | G5: =IF(OR($A5="",G$3=""),"",SUMIFS('Expense Log'!$I$5:$I$3000,'Expense Log'!$L$5:$L$3000,G$3,'Expense Log'!$C$5:$C$3000,$A5)) | H5: =IF(OR($A5="",H$3=""),"",SUMIFS('Expense Log'!$I$5:$I$3000,'Expense Log'!$L$5:$L$3000,H$3,'Expense Log'!$C$5:$C$3000,$A5)) | I5: =IF(OR($A5="",I$3=""),"",SUMIFS('Expense Log'!$I$5:$I$3000,'Expense Log'!$L$5:$L$3000,I$3,'Expense Log'!$C$5:$C$3000,$A5)) | ... Y5: =IF(OR($A5="",Y$3=""),"",SUMIFS('Expense Log'!$I$5:$I$3000,'Expense Log'!$L$5:$L$3000,Y$3,'Expense Log'!$C$5:$C$3000,$A5)) | Z5: =IF($A5="","",SUM(B5:Y5)) | AB5: =IF(INDEX($B$3:$Y$3,1)="","",INDEX($B$3:$Y$3,1))
A6: =IF(INDEX(Lists!$H$4:$AA$4,1,3)="","",INDEX(Lists!$H$4:$AA$4,1,3)) | B6: =IF(OR($A6="",B$3=""),"",SUMIFS('Expense Log'!$I$5:$I$3000,'Expense Log'!$L$5:$L$3000,B$3,'Expense Log'!$C$5:$C$3000,$A6)) | C6: =IF(OR($A6="",C$3=""),"",SUMIFS('Expense Log'!$I$5:$I$3000,'Expense Log'!$L$5:$L$3000,C$3,'Expense Log'!$C$5:$C$3000,$A6)) | D6: =IF(OR($A6="",D$3=""),"",SUMIFS('Expense Log'!$I$5:$I$3000,'Expense Log'!$L$5:$L$3000,D$3,'Expense Log'!$C$5:$C$3000,$A6)) | E6: =IF(OR($A6="",E$3=""),"",SUMIFS('Expense Log'!$I$5:$I$3000,'Expense Log'!$L$5:$L$3000,E$3,'Expense Log'!$C$5:$C$3000,$A6)) | F6: =IF(OR($A6="",F$3=""),"",SUMIFS('Expense Log'!$I$5:$I$3000,'Expense Log'!$L$5:$L$3000,F$3,'Expense Log'!$C$5:$C$3000,$A6)) | G6: =IF(OR($A6="",G$3=""),"",SUMIFS('Expense Log'!$I$5:$I$3000,'Expense Log'!$L$5:$L$3000,G$3,'Expense Log'!$C$5:$C$3000,$A6)) | H6: =IF(OR($A6="",H$3=""),"",SUMIFS('Expense Log'!$I$5:$I$3000,'Expense Log'!$L$5:$L$3000,H$3,'Expense Log'!$C$5:$C$3000,$A6)) | I6: =IF(OR($A6="",I$3=""),"",SUMIFS('Expense Log'!$I$5:$I$3000,'Expense Log'!$L$5:$L$3000,I$3,'Expense Log'!$C$5:$C$3000,$A6)) | ... Y6: =IF(OR($A6="",Y$3=""),"",SUMIFS('Expense Log'!$I$5:$I$3000,'Expense Log'!$L$5:$L$3000,Y$3,'Expense Log'!$C$5:$C$3000,$A6)) | Z6: =IF($A6="","",SUM(B6:Y6)) | AB6: =IF(INDEX($B$3:$Y$3,2)="","",INDEX($B$3:$Y$3,2))
A7: =IF(INDEX(Lists!$H$4:$AA$4,1,4)="","",INDEX(Lists!$H$4:$AA$4,1,4)) | B7: =IF(OR($A7="",B$3=""),"",SUMIFS('Expense Log'!$I$5:$I$3000,'Expense Log'!$L$5:$L$3000,B$3,'Expense Log'!$C$5:$C$3000,$A7)) | C7: =IF(OR($A7="",C$3=""),"",SUMIFS('Expense Log'!$I$5:$I$3000,'Expense Log'!$L$5:$L$3000,C$3,'Expense Log'!$C$5:$C$3000,$A7)) | D7: =IF(OR($A7="",D$3=""),"",SUMIFS('Expense Log'!$I$5:$I$3000,'Expense Log'!$L$5:$L$3000,D$3,'Expense Log'!$C$5:$C$3000,$A7)) | E7: =IF(OR($A7="",E$3=""),"",SUMIFS('Expense Log'!$I$5:$I$3000,'Expense Log'!$L$5:$L$3000,E$3,'Expense Log'!$C$5:$C$3000,$A7)) | F7: =IF(OR($A7="",F$3=""),"",SUMIFS('Expense Log'!$I$5:$I$3000,'Expense Log'!$L$5:$L$3000,F$3,'Expense Log'!$C$5:$C$3000,$A7)) | G7: =IF(OR($A7="",G$3=""),"",SUMIFS('Expense Log'!$I$5:$I$3000,'Expense Log'!$L$5:$L$3000,G$3,'Expense Log'!$C$5:$C$3000,$A7)) | H7: =IF(OR($A7="",H$3=""),"",SUMIFS('Expense Log'!$I$5:$I$3000,'Expense Log'!$L$5:$L$3000,H$3,'Expense Log'!$C$5:$C$3000,$A7)) | I7: =IF(OR($A7="",I$3=""),"",SUMIFS('Expense Log'!$I$5:$I$3000,'Expense Log'!$L$5:$L$3000,I$3,'Expense Log'!$C$5:$C$3000,$A7)) | ... Y7: =IF(OR($A7="",Y$3=""),"",SUMIFS('Expense Log'!$I$5:$I$3000,'Expense Log'!$L$5:$L$3000,Y$3,'Expense Log'!$C$5:$C$3000,$A7)) | Z7: =IF($A7="","",SUM(B7:Y7)) | AB7: =IF(INDEX($B$3:$Y$3,3)="","",INDEX($B$3:$Y$3,3))
A8: =IF(INDEX(Lists!$H$4:$AA$4,1,5)="","",INDEX(Lists!$H$4:$AA$4,1,5)) | B8: =IF(OR($A8="",B$3=""),"",SUMIFS('Expense Log'!$I$5:$I$3000,'Expense Log'!$L$5:$L$3000,B$3,'Expense Log'!$C$5:$C$3000,$A8)) | C8: =IF(OR($A8="",C$3=""),"",SUMIFS('Expense Log'!$I$5:$I$3000,'Expense Log'!$L$5:$L$3000,C$3,'Expense Log'!$C$5:$C$3000,$A8)) | D8: =IF(OR($A8="",D$3=""),"",SUMIFS('Expense Log'!$I$5:$I$3000,'Expense Log'!$L$5:$L$3000,D$3,'Expense Log'!$C$5:$C$3000,$A8)) | E8: =IF(OR($A8="",E$3=""),"",SUMIFS('Expense Log'!$I$5:$I$3000,'Expense Log'!$L$5:$L$3000,E$3,'Expense Log'!$C$5:$C$3000,$A8)) | F8: =IF(OR($A8="",F$3=""),"",SUMIFS('Expense Log'!$I$5:$I$3000,'Expense Log'!$L$5:$L$3000,F$3,'Expense Log'!$C$5:$C$3000,$A8)) | G8: =IF(OR($A8="",G$3=""),"",SUMIFS('Expense Log'!$I$5:$I$3000,'Expense Log'!$L$5:$L$3000,G$3,'Expense Log'!$C$5:$C$3000,$A8)) | H8: =IF(OR($A8="",H$3=""),"",SUMIFS('Expense Log'!$I$5:$I$3000,'Expense Log'!$L$5:$L$3000,H$3,'Expense Log'!$C$5:$C$3000,$A8)) | I8: =IF(OR($A8="",I$3=""),"",SUMIFS('Expense Log'!$I$5:$I$3000,'Expense Log'!$L$5:$L$3000,I$3,'Expense Log'!$C$5:$C$3000,$A8)) | ... Y8: =IF(OR($A8="",Y$3=""),"",SUMIFS('Expense Log'!$I$5:$I$3000,'Expense Log'!$L$5:$L$3000,Y$3,'Expense Log'!$C$5:$C$3000,$A8)) | Z8: =IF($A8="","",SUM(B8:Y8)) | AB8: =IF(INDEX($B$3:$Y$3,4)="","",INDEX($B$3:$Y$3,4))
A9: =IF(INDEX(Lists!$H$4:$AA$4,1,6)="","",INDEX(Lists!$H$4:$AA$4,1,6)) | B9: =IF(OR($A9="",B$3=""),"",SUMIFS('Expense Log'!$I$5:$I$3000,'Expense Log'!$L$5:$L$3000,B$3,'Expense Log'!$C$5:$C$3000,$A9)) | C9: =IF(OR($A9="",C$3=""),"",SUMIFS('Expense Log'!$I$5:$I$3000,'Expense Log'!$L$5:$L$3000,C$3,'Expense Log'!$C$5:$C$3000,$A9)) | D9: =IF(OR($A9="",D$3=""),"",SUMIFS('Expense Log'!$I$5:$I$3000,'Expense Log'!$L$5:$L$3000,D$3,'Expense Log'!$C$5:$C$3000,$A9)) | E9: =IF(OR($A9="",E$3=""),"",SUMIFS('Expense Log'!$I$5:$I$3000,'Expense Log'!$L$5:$L$3000,E$3,'Expense Log'!$C$5:$C$3000,$A9)) | F9: =IF(OR($A9="",F$3=""),"",SUMIFS('Expense Log'!$I$5:$I$3000,'Expense Log'!$L$5:$L$3000,F$3,'Expense Log'!$C$5:$C$3000,$A9)) | G9: =IF(OR($A9="",G$3=""),"",SUMIFS('Expense Log'!$I$5:$I$3000,'Expense Log'!$L$5:$L$3000,G$3,'Expense Log'!$C$5:$C$3000,$A9)) | H9: =IF(OR($A9="",H$3=""),"",SUMIFS('Expense Log'!$I$5:$I$3000,'Expense Log'!$L$5:$L$3000,H$3,'Expense Log'!$C$5:$C$3000,$A9)) | I9: =IF(OR($A9="",I$3=""),"",SUMIFS('Expense Log'!$I$5:$I$3000,'Expense Log'!$L$5:$L$3000,I$3,'Expense Log'!$C$5:$C$3000,$A9)) | ... Y9: =IF(OR($A9="",Y$3=""),"",SUMIFS('Expense Log'!$I$5:$I$3000,'Expense Log'!$L$5:$L$3000,Y$3,'Expense Log'!$C$5:$C$3000,$A9)) | Z9: =IF($A9="","",SUM(B9:Y9)) | AB9: =IF(INDEX($B$3:$Y$3,5)="","",INDEX($B$3:$Y$3,5))
A10: =IF(INDEX(Lists!$H$4:$AA$4,1,7)="","",INDEX(Lists!$H$4:$AA$4,1,7)) | B10: =IF(OR($A10="",B$3=""),"",SUMIFS('Expense Log'!$I$5:$I$3000,'Expense Log'!$L$5:$L$3000,B$3,'Expense Log'!$C$5:$C$3000,$A10)) | C10: =IF(OR($A10="",C$3=""),"",SUMIFS('Expense Log'!$I$5:$I$3000,'Expense Log'!$L$5:$L$3000,C$3,'Expense Log'!$C$5:$C$3000,$A10)) | D10: =IF(OR($A10="",D$3=""),"",SUMIFS('Expense Log'!$I$5:$I$3000,'Expense Log'!$L$5:$L$3000,D$3,'Expense Log'!$C$5:$C$3000,$A10)) | E10: =IF(OR($A10="",E$3=""),"",SUMIFS('Expense Log'!$I$5:$I$3000,'Expense Log'!$L$5:$L$3000,E$3,'Expense Log'!$C$5:$C$3000,$A10)) | F10: =IF(OR($A10="",F$3=""),"",SUMIFS('Expense Log'!$I$5:$I$3000,'Expense Log'!$L$5:$L$3000,F$3,'Expense Log'!$C$5:$C$3000,$A10)) | G10: =IF(OR($A10="",G$3=""),"",SUMIFS('Expense Log'!$I$5:$I$3000,'Expense Log'!$L$5:$L$3000,G$3,'Expense Log'!$C$5:$C$3000,$A10)) | H10: =IF(OR($A10="",H$3=""),"",SUMIFS('Expense Log'!$I$5:$I$3000,'Expense Log'!$L$5:$L$3000,H$3,'Expense Log'!$C$5:$C$3000,$A10)) | I10: =IF(OR($A10="",I$3=""),"",SUMIFS('Expense Log'!$I$5:$I$3000,'Expense Log'!$L$5:$L$3000,I$3,'Expense Log'!$C$5:$C$3000,$A10)) | ... Y10: =IF(OR($A10="",Y$3=""),"",SUMIFS('Expense Log'!$I$5:$I$3000,'Expense Log'!$L$5:$L$3000,Y$3,'Expense Log'!$C$5:$C$3000,$A10)) | Z10: =IF($A10="","",SUM(B10:Y10)) | AB10: =IF(INDEX($B$3:$Y$3,6)="","",INDEX($B$3:$Y$3,6))
A11: =IF(INDEX(Lists!$H$4:$AA$4,1,8)="","",INDEX(Lists!$H$4:$AA$4,1,8)) | B11: =IF(OR($A11="",B$3=""),"",SUMIFS('Expense Log'!$I$5:$I$3000,'Expense Log'!$L$5:$L$3000,B$3,'Expense Log'!$C$5:$C$3000,$A11)) | C11: =IF(OR($A11="",C$3=""),"",SUMIFS('Expense Log'!$I$5:$I$3000,'Expense Log'!$L$5:$L$3000,C$3,'Expense Log'!$C$5:$C$3000,$A11)) | D11: =IF(OR($A11="",D$3=""),"",SUMIFS('Expense Log'!$I$5:$I$3000,'Expense Log'!$L$5:$L$3000,D$3,'Expense Log'!$C$5:$C$3000,$A11)) | E11: =IF(OR($A11="",E$3=""),"",SUMIFS('Expense Log'!$I$5:$I$3000,'Expense Log'!$L$5:$L$3000,E$3,'Expense Log'!$C$5:$C$3000,$A11)) | F11: =IF(OR($A11="",F$3=""),"",SUMIFS('Expense Log'!$I$5:$I$3000,'Expense Log'!$L$5:$L$3000,F$3,'Expense Log'!$C$5:$C$3000,$A11)) | G11: =IF(OR($A11="",G$3=""),"",SUMIFS('Expense Log'!$I$5:$I$3000,'Expense Log'!$L$5:$L$3000,G$3,'Expense Log'!$C$5:$C$3000,$A11)) | H11: =IF(OR($A11="",H$3=""),"",SUMIFS('Expense Log'!$I$5:$I$3000,'Expense Log'!$L$5:$L$3000,H$3,'Expense Log'!$C$5:$C$3000,$A11)) | I11: =IF(OR($A11="",I$3=""),"",SUMIFS('Expense Log'!$I$5:$I$3000,'Expense Log'!$L$5:$L$3000,I$3,'Expense Log'!$C$5:$C$3000,$A11)) | ... Y11: =IF(OR($A11="",Y$3=""),"",SUMIFS('Expense Log'!$I$5:$I$3000,'Expense Log'!$L$5:$L$3000,Y$3,'Expense Log'!$C$5:$C$3000,$A11)) | Z11: =IF($A11="","",SUM(B11:Y11)) | AB11: =IF(INDEX($B$3:$Y$3,7)="","",INDEX($B$3:$Y$3,7))
A12: =IF(INDEX(Lists!$H$4:$AA$4,1,9)="","",INDEX(Lists!$H$4:$AA$4,1,9)) | B12: =IF(OR($A12="",B$3=""),"",SUMIFS('Expense Log'!$I$5:$I$3000,'Expense Log'!$L$5:$L$3000,B$3,'Expense Log'!$C$5:$C$3000,$A12)) | C12: =IF(OR($A12="",C$3=""),"",SUMIFS('Expense Log'!$I$5:$I$3000,'Expense Log'!$L$5:$L$3000,C$3,'Expense Log'!$C$5:$C$3000,$A12)) | D12: =IF(OR($A12="",D$3=""),"",SUMIFS('Expense Log'!$I$5:$I$3000,'Expense Log'!$L$5:$L$3000,D$3,'Expense Log'!$C$5:$C$3000,$A12)) | E12: =IF(OR($A12="",E$3=""),"",SUMIFS('Expense Log'!$I$5:$I$3000,'Expense Log'!$L$5:$L$3000,E$3,'Expense Log'!$C$5:$C$3000,$A12)) | F12: =IF(OR($A12="",F$3=""),"",SUMIFS('Expense Log'!$I$5:$I$3000,'Expense Log'!$L$5:$L$3000,F$3,'Expense Log'!$C$5:$C$3000,$A12)) | G12: =IF(OR($A12="",G$3=""),"",SUMIFS('Expense Log'!$I$5:$I$3000,'Expense Log'!$L$5:$L$3000,G$3,'Expense Log'!$C$5:$C$3000,$A12)) | H12: =IF(OR($A12="",H$3=""),"",SUMIFS('Expense Log'!$I$5:$I$3000,'Expense Log'!$L$5:$L$3000,H$3,'Expense Log'!$C$5:$C$3000,$A12)) | I12: =IF(OR($A12="",I$3=""),"",SUMIFS('Expense Log'!$I$5:$I$3000,'Expense Log'!$L$5:$L$3000,I$3,'Expense Log'!$C$5:$C$3000,$A12)) | ... Y12: =IF(OR($A12="",Y$3=""),"",SUMIFS('Expense Log'!$I$5:$I$3000,'Expense Log'!$L$5:$L$3000,Y$3,'Expense Log'!$C$5:$C$3000,$A12)) | Z12: =IF($A12="","",SUM(B12:Y12)) | AB12: =IF(INDEX($B$3:$Y$3,8)="","",INDEX($B$3:$Y$3,8))
A13: =IF(INDEX(Lists!$H$4:$AA$4,1,10)="","",INDEX(Lists!$H$4:$AA$4,1,10)) | B13: =IF(OR($A13="",B$3=""),"",SUMIFS('Expense Log'!$I$5:$I$3000,'Expense Log'!$L$5:$L$3000,B$3,'Expense Log'!$C$5:$C$3000,$A13)) | C13: =IF(OR($A13="",C$3=""),"",SUMIFS('Expense Log'!$I$5:$I$3000,'Expense Log'!$L$5:$L$3000,C$3,'Expense Log'!$C$5:$C$3000,$A13)) | D13: =IF(OR($A13="",D$3=""),"",SUMIFS('Expense Log'!$I$5:$I$3000,'Expense Log'!$L$5:$L$3000,D$3,'Expense Log'!$C$5:$C$3000,$A13)) | E13: =IF(OR($A13="",E$3=""),"",SUMIFS('Expense Log'!$I$5:$I$3000,'Expense Log'!$L$5:$L$3000,E$3,'Expense Log'!$C$5:$C$3000,$A13)) | F13: =IF(OR($A13="",F$3=""),"",SUMIFS('Expense Log'!$I$5:$I$3000,'Expense Log'!$L$5:$L$3000,F$3,'Expense Log'!$C$5:$C$3000,$A13)) | G13: =IF(OR($A13="",G$3=""),"",SUMIFS('Expense Log'!$I$5:$I$3000,'Expense Log'!$L$5:$L$3000,G$3,'Expense Log'!$C$5:$C$3000,$A13)) | H13: =IF(OR($A13="",H$3=""),"",SUMIFS('Expense Log'!$I$5:$I$3000,'Expense Log'!$L$5:$L$3000,H$3,'Expense Log'!$C$5:$C$3000,$A13)) | I13: =IF(OR($A13="",I$3=""),"",SUMIFS('Expense Log'!$I$5:$I$3000,'Expense Log'!$L$5:$L$3000,I$3,'Expense Log'!$C$5:$C$3000,$A13)) | ... Y13: =IF(OR($A13="",Y$3=""),"",SUMIFS('Expense Log'!$I$5:$I$3000,'Expense Log'!$L$5:$L$3000,Y$3,'Expense Log'!$C$5:$C$3000,$A13)) | Z13: =IF($A13="","",SUM(B13:Y13)) | AB13: =IF(INDEX($B$3:$Y$3,9)="","",INDEX($B$3:$Y$3,9))
A14: =IF(INDEX(Lists!$H$4:$AA$4,1,11)="","",INDEX(Lists!$H$4:$AA$4,1,11)) | B14: =IF(OR($A14="",B$3=""),"",SUMIFS('Expense Log'!$I$5:$I$3000,'Expense Log'!$L$5:$L$3000,B$3,'Expense Log'!$C$5:$C$3000,$A14)) | C14: =IF(OR($A14="",C$3=""),"",SUMIFS('Expense Log'!$I$5:$I$3000,'Expense Log'!$L$5:$L$3000,C$3,'Expense Log'!$C$5:$C$3000,$A14)) | D14: =IF(OR($A14="",D$3=""),"",SUMIFS('Expense Log'!$I$5:$I$3000,'Expense Log'!$L$5:$L$3000,D$3,'Expense Log'!$C$5:$C$3000,$A14)) | E14: =IF(OR($A14="",E$3=""),"",SUMIFS('Expense Log'!$I$5:$I$3000,'Expense Log'!$L$5:$L$3000,E$3,'Expense Log'!$C$5:$C$3000,$A14)) | F14: =IF(OR($A14="",F$3=""),"",SUMIFS('Expense Log'!$I$5:$I$3000,'Expense Log'!$L$5:$L$3000,F$3,'Expense Log'!$C$5:$C$3000,$A14)) | G14: =IF(OR($A14="",G$3=""),"",SUMIFS('Expense Log'!$I$5:$I$3000,'Expense Log'!$L$5:$L$3000,G$3,'Expense Log'!$C$5:$C$3000,$A14)) | H14: =IF(OR($A14="",H$3=""),"",SUMIFS('Expense Log'!$I$5:$I$3000,'Expense Log'!$L$5:$L$3000,H$3,'Expense Log'!$C$5:$C$3000,$A14)) | I14: =IF(OR($A14="",I$3=""),"",SUMIFS('Expense Log'!$I$5:$I$3000,'Expense Log'!$L$5:$L$3000,I$3,'Expense Log'!$C$5:$C$3000,$A14)) | ... Y14: =IF(OR($A14="",Y$3=""),"",SUMIFS('Expense Log'!$I$5:$I$3000,'Expense Log'!$L$5:$L$3000,Y$3,'Expense Log'!$C$5:$C$3000,$A14)) | Z14: =IF($A14="","",SUM(B14:Y14)) | AB14: =IF(INDEX($B$3:$Y$3,10)="","",INDEX($B$3:$Y$3,10))
A15: =IF(INDEX(Lists!$H$4:$AA$4,1,12)="","",INDEX(Lists!$H$4:$AA$4,1,12)) | B15: =IF(OR($A15="",B$3=""),"",SUMIFS('Expense Log'!$I$5:$I$3000,'Expense Log'!$L$5:$L$3000,B$3,'Expense Log'!$C$5:$C$3000,$A15)) | C15: =IF(OR($A15="",C$3=""),"",SUMIFS('Expense Log'!$I$5:$I$3000,'Expense Log'!$L$5:$L$3000,C$3,'Expense Log'!$C$5:$C$3000,$A15)) | D15: =IF(OR($A15="",D$3=""),"",SUMIFS('Expense Log'!$I$5:$I$3000,'Expense Log'!$L$5:$L$3000,D$3,'Expense Log'!$C$5:$C$3000,$A15)) | E15: =IF(OR($A15="",E$3=""),"",SUMIFS('Expense Log'!$I$5:$I$3000,'Expense Log'!$L$5:$L$3000,E$3,'Expense Log'!$C$5:$C$3000,$A15)) | F15: =IF(OR($A15="",F$3=""),"",SUMIFS('Expense Log'!$I$5:$I$3000,'Expense Log'!$L$5:$L$3000,F$3,'Expense Log'!$C$5:$C$3000,$A15)) | G15: =IF(OR($A15="",G$3=""),"",SUMIFS('Expense Log'!$I$5:$I$3000,'Expense Log'!$L$5:$L$3000,G$3,'Expense Log'!$C$5:$C$3000,$A15)) | H15: =IF(OR($A15="",H$3=""),"",SUMIFS('Expense Log'!$I$5:$I$3000,'Expense Log'!$L$5:$L$3000,H$3,'Expense Log'!$C$5:$C$3000,$A15)) | I15: =IF(OR($A15="",I$3=""),"",SUMIFS('Expense Log'!$I$5:$I$3000,'Expense Log'!$L$5:$L$3000,I$3,'Expense Log'!$C$5:$C$3000,$A15)) | ... Y15: =IF(OR($A15="",Y$3=""),"",SUMIFS('Expense Log'!$I$5:$I$3000,'Expense Log'!$L$5:$L$3000,Y$3,'Expense Log'!$C$5:$C$3000,$A15)) | Z15: =IF($A15="","",SUM(B15:Y15)) | AB15: =IF(INDEX($B$3:$Y$3,11)="","",INDEX($B$3:$Y$3,11))
A16: =IF(INDEX(Lists!$H$4:$AA$4,1,13)="","",INDEX(Lists!$H$4:$AA$4,1,13)) | B16: =IF(OR($A16="",B$3=""),"",SUMIFS('Expense Log'!$I$5:$I$3000,'Expense Log'!$L$5:$L$3000,B$3,'Expense Log'!$C$5:$C$3000,$A16)) | C16: =IF(OR($A16="",C$3=""),"",SUMIFS('Expense Log'!$I$5:$I$3000,'Expense Log'!$L$5:$L$3000,C$3,'Expense Log'!$C$5:$C$3000,$A16)) | D16: =IF(OR($A16="",D$3=""),"",SUMIFS('Expense Log'!$I$5:$I$3000,'Expense Log'!$L$5:$L$3000,D$3,'Expense Log'!$C$5:$C$3000,$A16)) | E16: =IF(OR($A16="",E$3=""),"",SUMIFS('Expense Log'!$I$5:$I$3000,'Expense Log'!$L$5:$L$3000,E$3,'Expense Log'!$C$5:$C$3000,$A16)) | F16: =IF(OR($A16="",F$3=""),"",SUMIFS('Expense Log'!$I$5:$I$3000,'Expense Log'!$L$5:$L$3000,F$3,'Expense Log'!$C$5:$C$3000,$A16)) | G16: =IF(OR($A16="",G$3=""),"",SUMIFS('Expense Log'!$I$5:$I$3000,'Expense Log'!$L$5:$L$3000,G$3,'Expense Log'!$C$5:$C$3000,$A16)) | H16: =IF(OR($A16="",H$3=""),"",SUMIFS('Expense Log'!$I$5:$I$3000,'Expense Log'!$L$5:$L$3000,H$3,'Expense Log'!$C$5:$C$3000,$A16)) | I16: =IF(OR($A16="",I$3=""),"",SUMIFS('Expense Log'!$I$5:$I$3000,'Expense Log'!$L$5:$L$3000,I$3,'Expense Log'!$C$5:$C$3000,$A16)) | ... Y16: =IF(OR($A16="",Y$3=""),"",SUMIFS('Expense Log'!$I$5:$I$3000,'Expense Log'!$L$5:$L$3000,Y$3,'Expense Log'!$C$5:$C$3000,$A16)) | Z16: =IF($A16="","",SUM(B16:Y16)) | AB16: =IF(INDEX($B$3:$Y$3,12)="","",INDEX($B$3:$Y$3,12))
A17: =IF(INDEX(Lists!$H$4:$AA$4,1,14)="","",INDEX(Lists!$H$4:$AA$4,1,14)) | B17: =IF(OR($A17="",B$3=""),"",SUMIFS('Expense Log'!$I$5:$I$3000,'Expense Log'!$L$5:$L$3000,B$3,'Expense Log'!$C$5:$C$3000,$A17)) | C17: =IF(OR($A17="",C$3=""),"",SUMIFS('Expense Log'!$I$5:$I$3000,'Expense Log'!$L$5:$L$3000,C$3,'Expense Log'!$C$5:$C$3000,$A17)) | D17: =IF(OR($A17="",D$3=""),"",SUMIFS('Expense Log'!$I$5:$I$3000,'Expense Log'!$L$5:$L$3000,D$3,'Expense Log'!$C$5:$C$3000,$A17)) | E17: =IF(OR($A17="",E$3=""),"",SUMIFS('Expense Log'!$I$5:$I$3000,'Expense Log'!$L$5:$L$3000,E$3,'Expense Log'!$C$5:$C$3000,$A17)) | F17: =IF(OR($A17="",F$3=""),"",SUMIFS('Expense Log'!$I$5:$I$3000,'Expense Log'!$L$5:$L$3000,F$3,'Expense Log'!$C$5:$C$3000,$A17)) | G17: =IF(OR($A17="",G$3=""),"",SUMIFS('Expense Log'!$I$5:$I$3000,'Expense Log'!$L$5:$L$3000,G$3,'Expense Log'!$C$5:$C$3000,$A17)) | H17: =IF(OR($A17="",H$3=""),"",SUMIFS('Expense Log'!$I$5:$I$3000,'Expense Log'!$L$5:$L$3000,H$3,'Expense Log'!$C$5:$C$3000,$A17)) | I17: =IF(OR($A17="",I$3=""),"",SUMIFS('Expense Log'!$I$5:$I$3000,'Expense Log'!$L$5:$L$3000,I$3,'Expense Log'!$C$5:$C$3000,$A17)) | ... Y17: =IF(OR($A17="",Y$3=""),"",SUMIFS('Expense Log'!$I$5:$I$3000,'Expense Log'!$L$5:$L$3000,Y$3,'Expense Log'!$C$5:$C$3000,$A17)) | Z17: =IF($A17="","",SUM(B17:Y17)) | AB17: =IF(INDEX($B$3:$Y$3,13)="","",INDEX($B$3:$Y$3,13))
A18: =IF(INDEX(Lists!$H$4:$AA$4,1,15)="","",INDEX(Lists!$H$4:$AA$4,1,15)) | B18: =IF(OR($A18="",B$3=""),"",SUMIFS('Expense Log'!$I$5:$I$3000,'Expense Log'!$L$5:$L$3000,B$3,'Expense Log'!$C$5:$C$3000,$A18)) | C18: =IF(OR($A18="",C$3=""),"",SUMIFS('Expense Log'!$I$5:$I$3000,'Expense Log'!$L$5:$L$3000,C$3,'Expense Log'!$C$5:$C$3000,$A18)) | D18: =IF(OR($A18="",D$3=""),"",SUMIFS('Expense Log'!$I$5:$I$3000,'Expense Log'!$L$5:$L$3000,D$3,'Expense Log'!$C$5:$C$3000,$A18)) | E18: =IF(OR($A18="",E$3=""),"",SUMIFS('Expense Log'!$I$5:$I$3000,'Expense Log'!$L$5:$L$3000,E$3,'Expense Log'!$C$5:$C$3000,$A18)) | F18: =IF(OR($A18="",F$3=""),"",SUMIFS('Expense Log'!$I$5:$I$3000,'Expense Log'!$L$5:$L$3000,F$3,'Expense Log'!$C$5:$C$3000,$A18)) | G18: =IF(OR($A18="",G$3=""),"",SUMIFS('Expense Log'!$I$5:$I$3000,'Expense Log'!$L$5:$L$3000,G$3,'Expense Log'!$C$5:$C$3000,$A18)) | H18: =IF(OR($A18="",H$3=""),"",SUMIFS('Expense Log'!$I$5:$I$3000,'Expense Log'!$L$5:$L$3000,H$3,'Expense Log'!$C$5:$C$3000,$A18)) | I18: =IF(OR($A18="",I$3=""),"",SUMIFS('Expense Log'!$I$5:$I$3000,'Expense Log'!$L$5:$L$3000,I$3,'Expense Log'!$C$5:$C$3000,$A18)) | ... Y18: =IF(OR($A18="",Y$3=""),"",SUMIFS('Expense Log'!$I$5:$I$3000,'Expense Log'!$L$5:$L$3000,Y$3,'Expense Log'!$C$5:$C$3000,$A18)) | Z18: =IF($A18="","",SUM(B18:Y18)) | AB18: =IF(INDEX($B$3:$Y$3,14)="","",INDEX($B$3:$Y$3,14))
A19: =IF(INDEX(Lists!$H$4:$AA$4,1,16)="","",INDEX(Lists!$H$4:$AA$4,1,16)) | B19: =IF(OR($A19="",B$3=""),"",SUMIFS('Expense Log'!$I$5:$I$3000,'Expense Log'!$L$5:$L$3000,B$3,'Expense Log'!$C$5:$C$3000,$A19)) | C19: =IF(OR($A19="",C$3=""),"",SUMIFS('Expense Log'!$I$5:$I$3000,'Expense Log'!$L$5:$L$3000,C$3,'Expense Log'!$C$5:$C$3000,$A19)) | D19: =IF(OR($A19="",D$3=""),"",SUMIFS('Expense Log'!$I$5:$I$3000,'Expense Log'!$L$5:$L$3000,D$3,'Expense Log'!$C$5:$C$3000,$A19)) | E19: =IF(OR($A19="",E$3=""),"",SUMIFS('Expense Log'!$I$5:$I$3000,'Expense Log'!$L$5:$L$3000,E$3,'Expense Log'!$C$5:$C$3000,$A19)) | F19: =IF(OR($A19="",F$3=""),"",SUMIFS('Expense Log'!$I$5:$I$3000,'Expense Log'!$L$5:$L$3000,F$3,'Expense Log'!$C$5:$C$3000,$A19)) | G19: =IF(OR($A19="",G$3=""),"",SUMIFS('Expense Log'!$I$5:$I$3000,'Expense Log'!$L$5:$L$3000,G$3,'Expense Log'!$C$5:$C$3000,$A19)) | H19: =IF(OR($A19="",H$3=""),"",SUMIFS('Expense Log'!$I$5:$I$3000,'Expense Log'!$L$5:$L$3000,H$3,'Expense Log'!$C$5:$C$3000,$A19)) | I19: =IF(OR($A19="",I$3=""),"",SUMIFS('Expense Log'!$I$5:$I$3000,'Expense Log'!$L$5:$L$3000,I$3,'Expense Log'!$C$5:$C$3000,$A19)) | ... Y19: =IF(OR($A19="",Y$3=""),"",SUMIFS('Expense Log'!$I$5:$I$3000,'Expense Log'!$L$5:$L$3000,Y$3,'Expense Log'!$C$5:$C$3000,$A19)) | Z19: =IF($A19="","",SUM(B19:Y19)) | AB19: =IF(INDEX($B$3:$Y$3,15)="","",INDEX($B$3:$Y$3,15))
A20: =IF(INDEX(Lists!$H$4:$AA$4,1,17)="","",INDEX(Lists!$H$4:$AA$4,1,17)) | B20: =IF(OR($A20="",B$3=""),"",SUMIFS('Expense Log'!$I$5:$I$3000,'Expense Log'!$L$5:$L$3000,B$3,'Expense Log'!$C$5:$C$3000,$A20)) | C20: =IF(OR($A20="",C$3=""),"",SUMIFS('Expense Log'!$I$5:$I$3000,'Expense Log'!$L$5:$L$3000,C$3,'Expense Log'!$C$5:$C$3000,$A20)) | D20: =IF(OR($A20="",D$3=""),"",SUMIFS('Expense Log'!$I$5:$I$3000,'Expense Log'!$L$5:$L$3000,D$3,'Expense Log'!$C$5:$C$3000,$A20)) | E20: =IF(OR($A20="",E$3=""),"",SUMIFS('Expense Log'!$I$5:$I$3000,'Expense Log'!$L$5:$L$3000,E$3,'Expense Log'!$C$5:$C$3000,$A20)) | F20: =IF(OR($A20="",F$3=""),"",SUMIFS('Expense Log'!$I$5:$I$3000,'Expense Log'!$L$5:$L$3000,F$3,'Expense Log'!$C$5:$C$3000,$A20)) | G20: =IF(OR($A20="",G$3=""),"",SUMIFS('Expense Log'!$I$5:$I$3000,'Expense Log'!$L$5:$L$3000,G$3,'Expense Log'!$C$5:$C$3000,$A20)) | H20: =IF(OR($A20="",H$3=""),"",SUMIFS('Expense Log'!$I$5:$I$3000,'Expense Log'!$L$5:$L$3000,H$3,'Expense Log'!$C$5:$C$3000,$A20)) | I20: =IF(OR($A20="",I$3=""),"",SUMIFS('Expense Log'!$I$5:$I$3000,'Expense Log'!$L$5:$L$3000,I$3,'Expense Log'!$C$5:$C$3000,$A20)) | ... Y20: =IF(OR($A20="",Y$3=""),"",SUMIFS('Expense Log'!$I$5:$I$3000,'Expense Log'!$L$5:$L$3000,Y$3,'Expense Log'!$C$5:$C$3000,$A20)) | Z20: =IF($A20="","",SUM(B20:Y20)) | AB20: =IF(INDEX($B$3:$Y$3,16)="","",INDEX($B$3:$Y$3,16))
A21: =IF(INDEX(Lists!$H$4:$AA$4,1,18)="","",INDEX(Lists!$H$4:$AA$4,1,18)) | B21: =IF(OR($A21="",B$3=""),"",SUMIFS('Expense Log'!$I$5:$I$3000,'Expense Log'!$L$5:$L$3000,B$3,'Expense Log'!$C$5:$C$3000,$A21)) | C21: =IF(OR($A21="",C$3=""),"",SUMIFS('Expense Log'!$I$5:$I$3000,'Expense Log'!$L$5:$L$3000,C$3,'Expense Log'!$C$5:$C$3000,$A21)) | D21: =IF(OR($A21="",D$3=""),"",SUMIFS('Expense Log'!$I$5:$I$3000,'Expense Log'!$L$5:$L$3000,D$3,'Expense Log'!$C$5:$C$3000,$A21)) | E21: =IF(OR($A21="",E$3=""),"",SUMIFS('Expense Log'!$I$5:$I$3000,'Expense Log'!$L$5:$L$3000,E$3,'Expense Log'!$C$5:$C$3000,$A21)) | F21: =IF(OR($A21="",F$3=""),"",SUMIFS('Expense Log'!$I$5:$I$3000,'Expense Log'!$L$5:$L$3000,F$3,'Expense Log'!$C$5:$C$3000,$A21)) | G21: =IF(OR($A21="",G$3=""),"",SUMIFS('Expense Log'!$I$5:$I$3000,'Expense Log'!$L$5:$L$3000,G$3,'Expense Log'!$C$5:$C$3000,$A21)) | H21: =IF(OR($A21="",H$3=""),"",SUMIFS('Expense Log'!$I$5:$I$3000,'Expense Log'!$L$5:$L$3000,H$3,'Expense Log'!$C$5:$C$3000,$A21)) | I21: =IF(OR($A21="",I$3=""),"",SUMIFS('Expense Log'!$I$5:$I$3000,'Expense Log'!$L$5:$L$3000,I$3,'Expense Log'!$C$5:$C$3000,$A21)) | ... Y21: =IF(OR($A21="",Y$3=""),"",SUMIFS('Expense Log'!$I$5:$I$3000,'Expense Log'!$L$5:$L$3000,Y$3,'Expense Log'!$C$5:$C$3000,$A21)) | Z21: =IF($A21="","",SUM(B21:Y21)) | AB21: =IF(INDEX($B$3:$Y$3,17)="","",INDEX($B$3:$Y$3,17))
A22: =IF(INDEX(Lists!$H$4:$AA$4,1,19)="","",INDEX(Lists!$H$4:$AA$4,1,19)) | B22: =IF(OR($A22="",B$3=""),"",SUMIFS('Expense Log'!$I$5:$I$3000,'Expense Log'!$L$5:$L$3000,B$3,'Expense Log'!$C$5:$C$3000,$A22)) | C22: =IF(OR($A22="",C$3=""),"",SUMIFS('Expense Log'!$I$5:$I$3000,'Expense Log'!$L$5:$L$3000,C$3,'Expense Log'!$C$5:$C$3000,$A22)) | D22: =IF(OR($A22="",D$3=""),"",SUMIFS('Expense Log'!$I$5:$I$3000,'Expense Log'!$L$5:$L$3000,D$3,'Expense Log'!$C$5:$C$3000,$A22)) | E22: =IF(OR($A22="",E$3=""),"",SUMIFS('Expense Log'!$I$5:$I$3000,'Expense Log'!$L$5:$L$3000,E$3,'Expense Log'!$C$5:$C$3000,$A22)) | F22: =IF(OR($A22="",F$3=""),"",SUMIFS('Expense Log'!$I$5:$I$3000,'Expense Log'!$L$5:$L$3000,F$3,'Expense Log'!$C$5:$C$3000,$A22)) | G22: =IF(OR($A22="",G$3=""),"",SUMIFS('Expense Log'!$I$5:$I$3000,'Expense Log'!$L$5:$L$3000,G$3,'Expense Log'!$C$5:$C$3000,$A22)) | H22: =IF(OR($A22="",H$3=""),"",SUMIFS('Expense Log'!$I$5:$I$3000,'Expense Log'!$L$5:$L$3000,H$3,'Expense Log'!$C$5:$C$3000,$A22)) | I22: =IF(OR($A22="",I$3=""),"",SUMIFS('Expense Log'!$I$5:$I$3000,'Expense Log'!$L$5:$L$3000,I$3,'Expense Log'!$C$5:$C$3000,$A22)) | ... Y22: =IF(OR($A22="",Y$3=""),"",SUMIFS('Expense Log'!$I$5:$I$3000,'Expense Log'!$L$5:$L$3000,Y$3,'Expense Log'!$C$5:$C$3000,$A22)) | Z22: =IF($A22="","",SUM(B22:Y22)) | AB22: =IF(INDEX($B$3:$Y$3,18)="","",INDEX($B$3:$Y$3,18))
A23: =IF(INDEX(Lists!$H$4:$AA$4,1,20)="","",INDEX(Lists!$H$4:$AA$4,1,20)) | B23: =IF(OR($A23="",B$3=""),"",SUMIFS('Expense Log'!$I$5:$I$3000,'Expense Log'!$L$5:$L$3000,B$3,'Expense Log'!$C$5:$C$3000,$A23)) | C23: =IF(OR($A23="",C$3=""),"",SUMIFS('Expense Log'!$I$5:$I$3000,'Expense Log'!$L$5:$L$3000,C$3,'Expense Log'!$C$5:$C$3000,$A23)) | D23: =IF(OR($A23="",D$3=""),"",SUMIFS('Expense Log'!$I$5:$I$3000,'Expense Log'!$L$5:$L$3000,D$3,'Expense Log'!$C$5:$C$3000,$A23)) | E23: =IF(OR($A23="",E$3=""),"",SUMIFS('Expense Log'!$I$5:$I$3000,'Expense Log'!$L$5:$L$3000,E$3,'Expense Log'!$C$5:$C$3000,$A23)) | F23: =IF(OR($A23="",F$3=""),"",SUMIFS('Expense Log'!$I$5:$I$3000,'Expense Log'!$L$5:$L$3000,F$3,'Expense Log'!$C$5:$C$3000,$A23)) | G23: =IF(OR($A23="",G$3=""),"",SUMIFS('Expense Log'!$I$5:$I$3000,'Expense Log'!$L$5:$L$3000,G$3,'Expense Log'!$C$5:$C$3000,$A23)) | H23: =IF(OR($A23="",H$3=""),"",SUMIFS('Expense Log'!$I$5:$I$3000,'Expense Log'!$L$5:$L$3000,H$3,'Expense Log'!$C$5:$C$3000,$A23)) | I23: =IF(OR($A23="",I$3=""),"",SUMIFS('Expense Log'!$I$5:$I$3000,'Expense Log'!$L$5:$L$3000,I$3,'Expense Log'!$C$5:$C$3000,$A23)) | ... Y23: =IF(OR($A23="",Y$3=""),"",SUMIFS('Expense Log'!$I$5:$I$3000,'Expense Log'!$L$5:$L$3000,Y$3,'Expense Log'!$C$5:$C$3000,$A23)) | Z23: =IF($A23="","",SUM(B23:Y23)) | AB23: =IF(INDEX($B$3:$Y$3,19)="","",INDEX($B$3:$Y$3,19))
A24: TOTAL SPENT | B24: =IF(B$3="","",SUMIFS('Expense Log'!$I$5:$I$3000,'Expense Log'!$L$5:$L$3000,B$3)) | C24: =IF(C$3="","",SUMIFS('Expense Log'!$I$5:$I$3000,'Expense Log'!$L$5:$L$3000,C$3)) | D24: =IF(D$3="","",SUMIFS('Expense Log'!$I$5:$I$3000,'Expense Log'!$L$5:$L$3000,D$3)) | E24: =IF(E$3="","",SUMIFS('Expense Log'!$I$5:$I$3000,'Expense Log'!$L$5:$L$3000,E$3)) | F24: =IF(F$3="","",SUMIFS('Expense Log'!$I$5:$I$3000,'Expense Log'!$L$5:$L$3000,F$3)) | G24: =IF(G$3="","",SUMIFS('Expense Log'!$I$5:$I$3000,'Expense Log'!$L$5:$L$3000,G$3)) | H24: =IF(H$3="","",SUMIFS('Expense Log'!$I$5:$I$3000,'Expense Log'!$L$5:$L$3000,H$3)) | I24: =IF(I$3="","",SUMIFS('Expense Log'!$I$5:$I$3000,'Expense Log'!$L$5:$L$3000,I$3)) | ... Y24: =IF(Y$3="","",SUMIFS('Expense Log'!$I$5:$I$3000,'Expense Log'!$L$5:$L$3000,Y$3)) | Z24: =SUM(B24:Y24) | AB24: =IF(INDEX($B$3:$Y$3,20)="","",INDEX($B$3:$Y$3,20))
A25: of which one-off | B25: =IF(B$3="","",SUMIFS('Expense Log'!$I$5:$I$3000,'Expense Log'!$L$5:$L$3000,B$3,'Expense Log'!$J$5:$J$3000,"Yes")) | C25: =IF(C$3="","",SUMIFS('Expense Log'!$I$5:$I$3000,'Expense Log'!$L$5:$L$3000,C$3,'Expense Log'!$J$5:$J$3000,"Yes")) | D25: =IF(D$3="","",SUMIFS('Expense Log'!$I$5:$I$3000,'Expense Log'!$L$5:$L$3000,D$3,'Expense Log'!$J$5:$J$3000,"Yes")) | E25: =IF(E$3="","",SUMIFS('Expense Log'!$I$5:$I$3000,'Expense Log'!$L$5:$L$3000,E$3,'Expense Log'!$J$5:$J$3000,"Yes")) | F25: =IF(F$3="","",SUMIFS('Expense Log'!$I$5:$I$3000,'Expense Log'!$L$5:$L$3000,F$3,'Expense Log'!$J$5:$J$3000,"Yes")) | G25: =IF(G$3="","",SUMIFS('Expense Log'!$I$5:$I$3000,'Expense Log'!$L$5:$L$3000,G$3,'Expense Log'!$J$5:$J$3000,"Yes")) | H25: =IF(H$3="","",SUMIFS('Expense Log'!$I$5:$I$3000,'Expense Log'!$L$5:$L$3000,H$3,'Expense Log'!$J$5:$J$3000,"Yes")) | I25: =IF(I$3="","",SUMIFS('Expense Log'!$I$5:$I$3000,'Expense Log'!$L$5:$L$3000,I$3,'Expense Log'!$J$5:$J$3000,"Yes")) | ... Y25: =IF(Y$3="","",SUMIFS('Expense Log'!$I$5:$I$3000,'Expense Log'!$L$5:$L$3000,Y$3,'Expense Log'!$J$5:$J$3000,"Yes")) | Z25: =SUM(B25:Y25) | AB25: =IF(INDEX($B$3:$Y$3,21)="","",INDEX($B$3:$Y$3,21))
A26: excluding one-off | B26: =IF(B$3="","",B24-B25) | C26: =IF(C$3="","",C24-C25) | D26: =IF(D$3="","",D24-D25) | E26: =IF(E$3="","",E24-E25) | F26: =IF(F$3="","",F24-F25) | G26: =IF(G$3="","",G24-G25) | H26: =IF(H$3="","",H24-H25) | I26: =IF(I$3="","",I24-I25) | ... Y26: =IF(Y$3="","",Y24-Y25) | Z26: =SUM(B26:Y26) | AB26: =IF(INDEX($B$3:$Y$3,22)="","",INDEX($B$3:$Y$3,22))
A27: not matched to a category (should be 0) | B27: =IF(B$3="","",B24-SUM(B4:B23)) | C27: =IF(C$3="","",C24-SUM(C4:C23)) | D27: =IF(D$3="","",D24-SUM(D4:D23)) | E27: =IF(E$3="","",E24-SUM(E4:E23)) | F27: =IF(F$3="","",F24-SUM(F4:F23)) | G27: =IF(G$3="","",G24-SUM(G4:G23)) | H27: =IF(H$3="","",H24-SUM(H4:H23)) | I27: =IF(I$3="","",I24-SUM(I4:I23)) | ... Y27: =IF(Y$3="","",Y24-SUM(Y4:Y23)) | Z27: =SUM(B27:Y27) | AB27: =IF(INDEX($B$3:$Y$3,23)="","",INDEX($B$3:$Y$3,23))
AB28: =IF(INDEX($B$3:$Y$3,24)="","",INDEX($B$3:$Y$3,24))
